Workbook

Sheet Cover & Method
A1: ISO/IEC 27001:2022 Gap Analysis
A2: Aldridge Financial Technologies | AFT-ISMS-GAP-01 | Version 2.0 | 9 September 2026 | Classification: Confidential
A5: ENGAGEMENT
A6: Assessed entity | B6: Aldridge Financial Technologies, Inc. and Aldridge Financial Technologies (UK) Ltd
A7: Standard | B7: ISO/IEC 27001:2022, including Annex A (93 controls) and management system clauses 4 to 10
A8: Assessment date | B8: September 2026
A9: Assessed by | B9: Security Governance (Chidi Eze), reviewed by the Chief Information Security Officer
A10: Certification target | B10: Stage 1 audit Q2 2027
A11: Basis of assessment | B11: Document review, control walkthroughs, system inspection and interview. No independent testing of operating effectiveness was performed; this is a gap analysis, not an audit.
A12: Source of record | B12: AFT-CTX-01 Organisation Context Pack v1.0
A14: SCOPE STATEMENT (DRAFT, NOT YET APPROVED)
B15: The information security management system supporting the design, development, operation and support of the Aldridge Pay, Aldridge Credit and Aldridge Ledger platforms, and the corporate functions that support them, delivered from AWS regions us-east-1, us-west-2 and eu-west-2 and from the company's offices in Austin, Texas and London, United Kingdom.
A17: IMPLEMENTATION STATUS SCALE
A18: Implemented | B18: Control is designed appropriately, operating, and evidenced.
A19: Partially implemented | B19: Control exists but has a design or operating deficiency, or lacks evidence.
A20: Not implemented | B20: Control is absent or exists only as intent.
A21: Not applicable | B21: Control does not apply. Justification required in the Statement of Applicability.
A23: MATURITY SCALE
A24: 0 — Non-existent | B24: No recognisable activity.
A25: 1 — Initial | B25: Ad hoc, dependent on individuals, undocumented.
A26: 2 — Repeatable | B26: Consistent in practice but not formally defined.
A27: 3 — Defined | B27: Documented, communicated, and performed consistently.
A28: 4 — Managed | B28: Measured, monitored, and reported with metrics.
A29: 5 — Optimised | B29: Continuously improved against measured outcomes.
A30: Certification threshold | B30: Maturity 3 is the minimum for a control to be certifiable. A gap is raised for any applicable control below 3.
A32: GAP PRIORITY
A33: P1 | B33: Prerequisite for audit readiness — the ISMS cannot be assessed without it. Target 31 January 2027.
A34: P2 | B34: Would generate a major nonconformity at Stage 2. Target 31 March 2027.
A35: P3 | B35: Would generate a minor nonconformity or an observation. Target 30 June 2027.
A36: P4 | B36: Improvement opportunity, not certification-blocking. Post-certification.
A38: IMPORTANT LIMITATION
B39: Annex A is a set of possible controls, not the certification requirement. Certification is granted against clauses 4 to 10. A company can implement every Annex A control and still fail. The 'Clause Gaps' tab is therefore the more consequential of the two registers and should be read first.

Sheet Summary
A1: Assessment Summary
A2: All figures are formulas driven by the 'Annex A Register' and 'Clause Gaps' tabs. Edit those tabs and these update.
A4: ANNEX A — IMPLEMENTATION STATUS
A5: Status | B5: Count | C5: % of applicable
A6: Implemented | B6: =COUNTIF('Annex A Register'!$G$4:$G$96,A6) -> 46 | C6: =IFERROR(B6/$B$11,0) -> 0.5
A7: Partially implemented | B7: =COUNTIF('Annex A Register'!$G$4:$G$96,A7) -> 43 | C7: =IFERROR(B7/$B$11,0) -> 0.4673913
A8: Not implemented | B8: =COUNTIF('Annex A Register'!$G$4:$G$96,A8) -> 3 | C8: =IFERROR(B8/$B$11,0) -> 0.032608696
A9: Not applicable | B9: =COUNTIF('Annex A Register'!$G$4:$G$96,A9) -> 1
A10: Total controls | B10: =COUNTA('Annex A Register'!$A$4:$A$96) -> 93
A11: Applicable controls | B11: =COUNTIF('Annex A Register'!$D$4:$D$96,"Yes") -> 92
A12: Controls with a gap | B12: =COUNTIFS('Annex A Register'!$D$4:$D$96,"Yes",'Annex A Register'!$I$4:$I$96,"<3") -> 46
A13: Conformance rate (applicable at maturity 3+) | B13: =IFERROR((B11-B12)/B11,0) -> 0.5
A15: ANNEX A — GAPS BY THEME
A16: Theme | B16: Controls | C16: Gaps | D16: Gap rate
A17: Organisational | B17: =COUNTIF('Annex A Register'!$C$4:$C$96,A17) -> 37 | C17: =COUNTIFS('Annex A Register'!$C$4:$C$96,A17,'Annex A Register'!$D$4:$D$96,"Yes",'Annex A Register'!$I$4:$I$96,"<3") -> 22 | D17: =IFERROR(C17/B17,0) -> 0.59459459
A18: People | B18: =COUNTIF('Annex A Register'!$C$4:$C$96,A18) -> 8 | C18: =COUNTIFS('Annex A Register'!$C$4:$C$96,A18,'Annex A Register'!$D$4:$D$96,"Yes",'Annex A Register'!$I$4:$I$96,"<3") -> 2 | D18: =IFERROR(C18/B18,0) -> 0.25
A19: Physical | B19: =COUNTIF('Annex A Register'!$C$4:$C$96,A19) -> 14 | C19: =COUNTIFS('Annex A Register'!$C$4:$C$96,A19,'Annex A Register'!$D$4:$D$96,"Yes",'Annex A Register'!$I$4:$I$96,"<3") -> 5 | D19: =IFERROR(C19/B19,0) -> 0.35714286
A20: Technological | B20: =COUNTIF('Annex A Register'!$C$4:$C$96,A20) -> 34 | C20: =COUNTIFS('Annex A Register'!$C$4:$C$96,A20,'Annex A Register'!$D$4:$D$96,"Yes",'Annex A Register'!$I$4:$I$96,"<3") -> 17 | D20: =IFERROR(C20/B20,0) -> 0.5
A23: GAPS BY PRIORITY
A24: Priority | B24: Annex A gaps | C24: Clause gaps | D24: Total
A25: P1 | B25: =COUNTIF('Annex A Register'!$K$4:$K$96,A25) -> 3 | C25: =COUNTIF('Clause Gaps'!$G$4:$G$28,A25) -> 14 | D25: =B25+C25 -> 17
A26: P2 | B26: =COUNTIF('Annex A Register'!$K$4:$K$96,A26) -> 29 | C26: =COUNTIF('Clause Gaps'!$G$4:$G$28,A26) -> 8 | D26: =B26+C26 -> 37
A27: P3 | B27: =COUNTIF('Annex A Register'!$K$4:$K$96,A27) -> 12 | C27: =COUNTIF('Clause Gaps'!$G$4:$G$28,A27) -> 2 | D27: =B27+C27 -> 14
A28: P4 | B28: =COUNTIF('Annex A Register'!$K$4:$K$96,A28) -> 2 | C28: =COUNTIF('Clause Gaps'!$G$4:$G$28,A28) -> 0 | D28: =B28+C28 -> 2
A29: Total | B29: =SUM(B25:B28) -> 46 | C29: =SUM(C25:C28) -> 24 | D29: =SUM(D25:D28) -> 70
A31: MANAGEMENT SYSTEM CLAUSES 4–10
A32: Status | B32: Count | C32: % of clauses
A33: Implemented | B33: =COUNTIF('Clause Gaps'!$E$4:$E$28,A33) -> 1 | C33: =IFERROR(B33/$B$36,0) -> 0.04
A34: Partially implemented | B34: =COUNTIF('Clause Gaps'!$E$4:$E$28,A34) -> 14 | C34: =IFERROR(B34/$B$36,0) -> 0.56
A35: Not implemented | B35: =COUNTIF('Clause Gaps'!$E$4:$E$28,A35) -> 10 | C35: =IFERROR(B35/$B$36,0) -> 0.4
A36: Total clause requirements | B36: =COUNTA('Clause Gaps'!$A$4:$A$28) -> 25
A38: READING THE NUMBERS
A39: The Annex A conformance rate is respectable for a company that has never run an ISMS, and reflects control maturity inherited from PCI DSS and SOC 2. The clause 4-10 position is the opposite and is the real finding: the management system that ISO/IEC 27001 actually certifies does not yet exist. Closing Annex A gaps without building the management system would not produce a certifiable organisation.

Sheet Annex A Register
A1: Annex A Control Register — all 93 controls
A2: Every assessment is supported by the evidence named in column F. Effort is internal person-days; cost is indicative external spend.
A3: Ref | B3: Control title | C3: Theme | D3: Applicable | E3: Current state | F3: Evidence reviewed | G3: Status | H3: Design / operating | I3: Maturity | J3: Gap description | K3: Priority | L3: Remediation action | M3: Effort (days) | N3: External cost (USD) | O3: Predecessor | P3: Owner | Q3: Target date | R3: Ref (CTX)
A4: A.5.1 | B4: Policies for information security | C4: Organisational | D4: Yes | E4: Four Tier 2 policies issued and current (POL-01 to POL-04). Secure development, cryptography, business continuity and TPRM policies also issued. No Tier 1 apex Information Security Policy exists. | F4: Policy library index reviewed 2 Sep 2026 (9 documents). No Tier 1 policy located. Interview: Head of Security Governance. | G4: Partially implemented | I4: 2 | J4: There is no top-level Information Security Policy establishing the ISMS, management commitment and the policy framework. AFT-ISMS-POL-05 is listed in the document register but has never been written. Policies are not linked to a Statement of Applicability. | K4: P1 | L4: Draft, approve and publish AFT-ISMS-POL-05 Information Security Policy at Tier 1, signed by the CEO. Map every Tier 2 policy and standard to it and to the SoA. Establish an annual policy review calendar. | M4: 8 | N4: — | O4: — | P4: Helen Achebe-Ward | Q4: 31 Jan 2027 | R4: POL-05
A5: A.5.2 | B5: Information security roles and responsibilities | C5: Organisational | D5: Yes | E5: Roles are described within individual policies. Security function is established with named leaders. No consolidated RACI across the ISMS. | F5: POL-01 to POL-09 role sections reviewed. No consolidated RACI produced on request. | G5: Partially implemented | I5: 2 | J5: Responsibilities are distributed across policy documents rather than defined once and maintained. No documented allocation of ISMS-specific responsibilities (risk owner, control owner, ISMS manager). | K5: P2 | L5: Produce a single ISMS roles and responsibilities matrix covering all Annex A control owners and clause responsibilities. Ratify at the Executive Risk Committee and reference it from POL-05. | M5: 6 | N5: — | O5: 5.2 | P5: Chidi Eze | Q5: 31 Mar 2027
A6: A.5.3 | B6: Segregation of duties | C6: Organisational | D6: Yes | E6: Principle stated in POL-03 section 3. Conflicting access is refused at request stage on reviewer judgement. Change and deployment duties are separated in CI/CD. | F6: Okta group configuration inspected. No SoD matrix produced on request. Interview: Head of Identity and Access. | G6: Partially implemented | I6: 2 | J6: No documented segregation of duties matrix defining which role combinations are conflicting. Detection relies on the approver recognising a conflict rather than on a defined rule set. | K6: P2 | L6: Build a segregation of duties conflict matrix for finance, payments, lending and platform roles. Encode the rules in Okta and the access request workflow so conflicts are blocked, not judged. | M6: 12 | N6: — | O6: A.5.9 | P6: Ruth Nakamura | Q6: 31 Mar 2027
A7: A.5.4 | B7: Management responsibilities | C7: Organisational | D7: Yes | E7: Executive Risk Committee meets monthly and receives security reporting. Security Steering Group meets fortnightly. | F7: ERC terms of reference and 6 months of minutes reviewed (Mar-Aug 2026). No ISMS standing item present. | G7: Partially implemented | I7: 2 | J7: Management direction is exercised in practice but not documented as an ISMS obligation. No evidence that management requires all personnel to apply information security in accordance with established policies. | K7: P2 | L7: Document management responsibilities in POL-05. Add a standing ISMS agenda item to the ERC with recorded decisions and actions. | M7: 3 | N7: — | O7: 5.2 | P7: Helen Achebe-Ward | Q7: 31 Mar 2027
A8: A.5.5 | B8: Contact with authorities | C8: Organisational | D8: Yes | E8: POL-02 defines the notification matrix and routes for the ICO, FCA, payment brands, acquirer and state regulators. Named contacts held by Legal and the DPO. | F8: POL-02 s7 notification matrix reviewed. Contact list for ICO, FCA, acquirer inspected, dated Jul 2026. | G8: Implemented | H8: Design and operation adequate | I8: 3
A9: A.5.6 | B9: Contact with special interest groups | C9: Organisational | D9: Yes | E9: SOC analysts hold personal memberships of FS-ISAC and regional security forums. No organisational membership or defined participation. | F9: Interview: Head of Security Operations. No organisational membership records produced. | G9: Partially implemented | I9: 2 | J9: Participation is individual and informal. If the analysts concerned left, the contact would be lost. No process for disseminating what is learned. | K9: P3 | L9: Take out organisational FS-ISAC membership. Define named representatives and deputies, and a route for intelligence received to reach the SOC and the Security Steering Group. | M9: 2 | N9: 8000 | O9: — | P9: Tomas Vidal | Q9: 30 Jun 2027
A10: A.5.7 | B10: Threat intelligence | C10: Organisational | D10: Yes | E10: The SOC consumes vendor feeds bundled with CrowdStrike and Wiz. No defined intelligence requirements, no strategic or tactical intelligence process, no dissemination. | F10: Interview: SOC lead analyst. No intelligence requirements document exists. CrowdStrike and Wiz feed configuration inspected. | G10: Not implemented | H10: Design absent | I10: 1 | J10: Threat intelligence is a by-product of tooling rather than a control. There are no documented intelligence requirements, no assessment of relevance to Aldridge's threat profile, and no linkage into risk assessment or control selection. | K10: P2 | L10: Define priority intelligence requirements based on the payments and lending threat landscape. Formalise collection sources, analysis cadence and dissemination to the SOC, engineering and the Security Steering Group. Feed intelligence into the risk assessment cycle. | M10: 20 | N10: 60000 | O10: — | P10: Tomas Vidal | Q10: 31 Mar 2027 | R10: W-05
A11: A.5.8 | B11: Information security in project management | C11: Organisational | D11: Yes | E11: Security is engaged on large initiatives by relationship rather than by process. No security gate in the delivery lifecycle. | F11: Delivery lifecycle checklist reviewed. Sample of 6 projects initiated 2026: security engagement recorded in 2. | G11: Partially implemented | I11: 2 | J11: Security involvement depends on whether a team thinks to ask. Smaller projects and product changes proceed without any security consideration being recorded. | K11: P2 | L11: Introduce a mandatory security assessment step at project initiation, sized by risk. Add security sign-off to the delivery lifecycle checklist and record it in Jira. | M11: 10 | N11: — | O11: 5.2 | P11: Marcus Lindqvist | Q11: 31 Mar 2027
A12: A.5.9 | B12: Inventory of information and other associated assets | C12: Organisational | D12: Yes | E12: Infrastructure assets are well inventoried through Wiz and Terraform state. Information assets are catalogued for the CDE and secure data zone. Approximately 40 SaaS applications identified by CASB in August 2026 are not registered. | F12: Asset register export 1 Sep 2026 (1,247 entries). CASB discovery report Aug 2026 reconciled: 40 applications unmatched. | G12: Partially implemented | H12: Design adequate; operation deficient (inventory not maintained) | I12: 2 | J12: The asset inventory is materially incomplete. Unregistered SaaS applications have no recorded owner, classification, or assessment, which means neither the risk assessment nor the ISMS scope can be relied upon. | K12: P1 | L12: Reconcile the CASB discovery output against the asset register. Assign an owner and classification to every application, or decommission it. Establish monthly CASB-to-register reconciliation as a standing control. | M12: 30 | N12: — | O12: — | P12: Claire Bennett | Q12: 31 Jan 2027 | R12: W-04
A13: A.5.10 | B13: Acceptable use of information and other associated assets | C13: Organisational | D13: Yes | E13: POL-01 v2.1 issued and current, covering endpoints, communications, cloud, generative AI and remote working. Acknowledged at onboarding. | F13: POL-01 v2.1 reviewed. Acknowledgement records sampled, 20 of 20 present. | G13: Implemented | H13: Design and operation adequate | I13: 4
A14: A.5.11 | B14: Return of assets | C14: Organisational | D14: Yes | E14: PRO-03 requires recovery of devices and credentials on or before the final working day. Tracked in the HRIS offboarding workflow. | F14: PRO-03 reviewed. Sample of 10 leavers Q2 2026: asset recovery evidenced in 10. | G14: Implemented | H14: Design and operation adequate | I14: 3
A15: A.5.12 | B15: Classification of information | C15: Organisational | D15: Yes | E15: POL-04 v2.0 defines four levels with owner accountability and an aggregation rule. Applied consistently in the CDE and secure data zone. | F15: POL-04 v2.0 reviewed. Data catalogue inspected for CDE and secure data zone. | G15: Implemented | H15: Design and operation adequate | I15: 3
A16: A.5.13 | B16: Labelling of information | C16: Organisational | D16: Yes | E16: Sensitivity labelling deployed in Google Workspace. Document footers required by POL-04. Adoption measured at approximately 60% of eligible documents. | F16: Google Workspace labelling configuration inspected. Adoption report 31 Aug 2026: 61% of eligible documents labelled. | G16: Partially implemented | H16: Design adequate; operation deficient (adoption at 61%) | I16: 2 | J16: Labelling is required by policy but not enforced or consistently applied. Unlabelled Confidential material circulates, which undermines the data loss prevention rules that depend on labels. | K16: P3 | L16: Enable default labelling and mandatory label prompts in Google Workspace. Run a labelling remediation campaign on existing shared drives. Report adoption monthly until above 95%. | M16: 12 | N16: — | O16: A.5.9 | P16: Claire Bennett | Q16: 30 Jun 2027
A17: A.5.14 | B17: Information transfer | C17: Organisational | D17: Yes | E17: POL-04 section 6.2 prohibits email for Restricted data and mandates the secure transfer platform. Managed links with expiry for Confidential data. NDAs required before external sharing. | F17: POL-04 s6.2 reviewed. Secure transfer platform configuration inspected. Sharing link audit sampled. | G17: Implemented | H17: Design and operation adequate | I17: 3
A18: A.5.15 | B18: Access control | C18: Organisational | D18: Yes | E18: POL-03 v2.2 establishes least privilege, need to know, deny by default and time-bound privilege. Enforced through Okta and CyberArk. | F18: POL-03 v2.2 reviewed. Okta policy configuration inspected. | G18: Implemented | H18: Design and operation adequate | I18: 4
A19: A.5.16 | B19: Identity management | C19: Organisational | D19: Yes | E19: Okta is the authoritative identity provider. Unique identities for all workers. Service accounts have named owners and non-interactive login only. | F19: Okta directory inspected 3 Sep 2026: 610 active identities, 0 shared interactive accounts, 84 service accounts all with named owner. | G19: Implemented | H19: Design and operation adequate | I19: 4
A20: A.5.17 | B20: Authentication information | C20: Organisational | D20: Yes | E20: MFA universal. Phishing-resistant FIDO2 mandatory for privileged access. Credentials held in HashiCorp Vault. Breached-password screening at set and at use. | F20: Okta authentication policy inspected. Vault configuration reviewed. FIDO2 enrolment: 100% of 41 privileged holders. | G20: Implemented | H20: Design and operation adequate | I20: 4
A21: A.5.18 | B21: Access rights | C21: Organisational | D21: Yes | E21: Quarterly recertification for all entitlements, monthly for privileged and CDE access. Automatic revocation of unconfirmed access. Leaver revocation within four hours, evidenced. | F21: Q2 2026 recertification campaign records reviewed: 100% completion, 214 entitlements revoked. Leaver revocation sample of 15: all within 4 hours. | G21: Implemented | H21: Design and operation adequate | I21: 4
A22: A.5.19 | B22: Information security in supplier relationships | C22: Organisational | D22: Yes | E22: POL-09 v1.3 requires assessment before onboarding. Procurement gatekeeps new supplier engagement. Assessment is performed at onboarding for all Tier 1 and Tier 2 suppliers. | F22: POL-09 v1.3 reviewed. Supplier onboarding records sampled, 8 of 8 assessed at onboarding. No offboarding security requirements located. | G22: Partially implemented | I22: 2 | J22: The process is defined for new suppliers but there is no documented approach to managing security across the supplier lifecycle, and no exit or termination security requirements. | K22: P2 | L22: Extend POL-09 to cover the full supplier lifecycle including offboarding, data return and destruction. Define security requirements for supplier exit and test them on the next termination. | M22: 8 | N22: — | O22: — | P22: Elena Petrova | Q22: 31 Mar 2027 | R22: W-08
A23: A.5.20 | B23: Addressing information security within supplier agreements | C23: Organisational | D23: Yes | E23: Standard security schedule applied to contracts executed since 2023, covering incident notification within 24 hours, audit rights and data handling. | F23: Contract register reviewed. 8 of 34 Tier 1/2 agreements lack the 2023 security schedule; list obtained from Legal. | G23: Partially implemented | H23: Design adequate for new contracts; legacy population outside scope of the design | I23: 2 | J23: Contracts predating 2023 do not carry the standard security schedule. Eight Tier 1 and Tier 2 suppliers, including Northgate Analytics, are on legacy paper with weaker or absent security terms. | K23: P2 | L23: Identify all Tier 1 and Tier 2 agreements lacking the current security schedule. Prioritise renegotiation at next renewal, and seek immediate amendment for Tier 1 suppliers on the critical path. | M23: 15 | N23: 25000 | O23: A.5.19 | P23: Jonathan Reyes | Q23: 31 Mar 2027 | R23: W-08
A24: A.5.21 | B24: Managing information security in the ICT supply chain | C24: Organisational | D24: Yes | E24: No process exists. Subcontractors and fourth parties used by suppliers are not identified, disclosed or assessed. | F24: Interview: Head of Procurement. No subcontractor register exists. TPRM questionnaire reviewed: no disclosure question present at assessment date. | G24: Not implemented | H24: Design absent | I24: 1 | J24: Aldridge has no visibility of the onward supply chain. It cannot answer where its data physically resides beyond the first tier, which is a direct exposure given Restricted data is shared with Tier 1 suppliers. | K24: P2 | L24: Add mandatory subcontractor disclosure to the TPRM questionnaire and to contract terms, with a notification obligation before any change. Map the fourth parties of all Tier 1 suppliers. | M24: 15 | N24: — | O24: A.5.19 | P24: Elena Petrova | Q24: 31 Mar 2027
A25: A.5.22 | B25: Monitoring, review and change management of supplier services | C25: Organisational | D25: Yes | E25: Reassessment is required annually for Tier 1 and Tier 2 by POL-09. Eleven of thirty-four Tier 1 and Tier 2 suppliers are overdue. Northgate Analytics (V-01) was last assessed in October 2024. | F25: Reassessment tracker reviewed 2 Sep 2026: 11 of 34 Tier 1/2 overdue. Northgate last assessment dated Oct 2024. | G25: Partially implemented | H25: Design adequate; operation deficient (reassessment not performed) | I25: 2 | J25: The reassessment obligation is defined but not performed. A critical-path supplier handling Restricted cardholder data has not been assessed for 23 months. There is no ongoing monitoring of supplier performance against security terms between assessments. | K25: P2 | L25: Clear the reassessment backlog, Tier 1 first, by 31 January 2027. Implement continuous supplier monitoring for Tier 1. Add reassessment due dates to the procurement system with automated escalation to the CISO at 30 days overdue. | M25: 35 | N25: — | O25: A.5.19 | P25: Elena Petrova | Q25: 31 Mar 2027 | R25: W-08
A26: A.5.23 | B26: Information security for use of cloud services | C26: Organisational | D26: Yes | E26: AWS is well governed with landing zones, guardrails, Wiz posture management and Terraform. SaaS acquisition is governed by POL-01 section 3.6 but not enforced technically. Approximately 40 unregistered SaaS applications are in use. | F26: AWS landing zone and Wiz configuration inspected. CASB report Aug 2026: 40 unregistered applications, 11 handling apparent Confidential content. | G26: Partially implemented | I26: 2 | J26: Cloud governance is strong for infrastructure and weak for software as a service. Unregistered applications may be processing Confidential or Restricted data with no assessment, no contract and no exit provision, and they fall outside the declared ISMS scope. | K26: P1 | L26: Triage the 40 discovered applications by data classification. Block or sanction each one. Route SaaS procurement through Okta and Procurement so that acquisition without assessment is not technically possible. | M26: 25 | N26: 30000 | O26: A.5.9 | P26: Sanjay Mehta | Q26: 31 Jan 2027 | R26: W-04
A27: A.5.24 | B27: Information security incident management planning and preparation | C27: Organisational | D27: Yes | E27: POL-02 v3.0 and PLN-01 runbooks issued. Named Incident Commanders with deputies. DFIR retainer in place. Two tabletop exercises completed in 2026, one with executive participation. | F27: POL-02 v3.0 and PLN-01 runbooks reviewed. DFIR retainer agreement inspected. Exercise reports Feb and Jul 2026 reviewed. | G27: Implemented | H27: Design and operation adequate | I27: 4
A28: A.5.25 | B28: Assessment and decision on information security events | C28: Organisational | D28: Yes | E28: Four-tier severity model with documented triage criteria. Provisional severity assigned at triage and reassessed as facts change. | F28: Triage criteria reviewed. Sample of 30 events Q2 2026: severity assigned in 30, reassessed in 4. | G28: Implemented | H28: Design and operation adequate | I28: 4
A29: A.5.26 | B29: Response to information security incidents | C29: Organisational | D29: Yes | E29: Six-phase lifecycle aligned to NIST SP 800-61. Incident Commander holds decision authority. Response evidenced across 2026 incidents. | F29: Incident records for 3 S2 and 1 S3 incident in 2026 reviewed end to end. | G29: Implemented | H29: Design and operation adequate | I29: 4
A30: A.5.27 | B30: Learning from information security incidents | C30: Organisational | D30: Yes | E30: Blameless post-incident review mandatory for S1 and S2. Actions assigned with owners and due dates and tracked to closure at the ERC. | F30: Post-incident review reports for 3 incidents reviewed. Action tracker inspected: 14 of 17 actions closed. | G30: Implemented | H30: Design and operation adequate | I30: 3
A31: A.5.28 | B31: Collection of evidence | C31: Organisational | D31: Yes | E31: STD-08 Digital Evidence Handling Standard issued. Chain of custody documented. Forensic imaging performed before rebuild. External DFIR provider retained. | F31: STD-08 reviewed. Chain of custody records for the Apr 2026 incident inspected. | G31: Implemented | H31: Design and operation adequate | I31: 3
A32: A.5.29 | B32: Information security during disruption | C32: Organisational | D32: Yes | E32: PLN-03 issued covering continuity and recovery. Component-level failover tested quarterly. No end-to-end test since March 2025. | F32: POL-08 and PLN-03 reviewed. Last full exercise report dated Mar 2025. | G32: Partially implemented | I32: 2 | J32: Continuity arrangements are documented but unproven at whole-service level. The recovery time objectives stated for A-01, A-02, A-10, A-11, A-12 and A-15 have not been validated in an integrated test. | K32: P2 | L32: Run a full end-to-end disaster recovery exercise for Aldridge Pay and the identity and secrets platforms by 31 March 2027. Record actual against target RTO and revise PLN-03 with the observed results. | M32: 10 | N32: — | O32: A.5.30 | P32: Sanjay Mehta | Q32: 31 Mar 2027 | R32: W-07
A33: A.5.30 | B33: ICT readiness for business continuity | C33: Organisational | D33: Yes | E33: Multi-availability-zone architecture with cross-region DR. Backups automated and encrypted. Recovery procedures documented per service. | F33: PLN-03 recovery procedures reviewed. Quarterly component failover test results Q1 and Q2 2026 inspected. | G33: Partially implemented | I33: 2 | J33: ICT readiness is designed but not verified. Restore testing is performed at component level only; a full restore of the Aldridge Credit servicing estate has never been performed. | K33: P2 | L33: Extend the DR exercise programme to cover full restore of A-03, A-04 and A-05. Test at least annually thereafter and report results to the ERC. | M33: 20 | N33: — | O33: A.8.14 | P33: Sanjay Mehta | Q33: 31 Mar 2027 | R33: W-07
A34: A.5.31 | B34: Legal, statutory, regulatory and contractual requirements | C34: Organisational | D34: Yes | E34: Legal maintains an obligations register covering PCI DSS, state money transmitter licences, FCA rules, UK GDPR and state breach laws. Reviewed quarterly. | F34: Obligations register reviewed 2 Sep 2026. Quarterly review evidenced for Q1 and Q2 2026. | G34: Implemented | H34: Design and operation adequate | I34: 3
A35: A.5.32 | B35: Intellectual property rights | C35: Organisational | D35: Yes | E35: Software licensing managed through Jamf and Intune for managed applications. Open source licence scanning in CI. | F35: Jamf and Intune licence reports reviewed. SCA licence scanning configuration inspected. No SAM process located. | G35: Partially implemented | I35: 2 | J35: Licence position for the approximately 40 unregistered SaaS applications is unknown, as is whether any are being used beyond their licensed terms. | K35: P3 | L35: Include licence compliance in the SaaS triage exercise under A.5.23. Establish a software asset management process covering acquisition and true-up. | M35: 5 | N35: — | O35: A.5.23 | P35: Sanjay Mehta | Q35: 30 Jun 2027 | R35: W-04
A36: A.5.33 | B36: Protection of records | C36: Organisational | D36: Yes | E36: SCH-01 Records Retention Schedule published. Legal hold process operated by the General Counsel. Records protected by access control and encryption. | F36: SCH-01 reviewed. Snowflake retention query executed with the data team 4 Sep 2026: borrower records identified predating the stated period. | G36: Partially implemented | H36: Design adequate; operation deficient (schedule not enforced) | I36: 2 | J36: The retention schedule is not technically enforced. Borrower data in Snowflake (A-09) is held beyond the stated retention period, so records are retained without a lawful or business basis. | K36: P2 | L36: Implement automated retention enforcement in Snowflake and the secure data zone. Reconcile actual retention against SCH-01 and remediate the existing overage. Report exceptions quarterly. | M36: 25 | N36: — | O36: A.5.9 | P36: Claire Bennett | Q36: 31 Mar 2027 | R36: W-09
A37: A.5.34 | B37: Privacy and protection of personal identifiable information | C37: Organisational | D37: Yes | E37: DPO appointed. Privacy notices published. DPIAs performed for new processing. Lawful transfer mechanisms documented for cross-border flows. | F37: LEG-POL-01, privacy notices and 4 DPIAs reviewed. Interview: Data Protection Officer. | G37: Partially implemented | I37: 2 | J37: The privacy framework is sound in design but is undermined by the retention overage at A.5.33, which breaches the UK GDPR storage limitation principle for identifiable borrower data. | K37: P2 | L37: Close the retention gap under A.5.33. Add a privacy compliance measure to the quarterly DPO report covering retention conformance and DPIA completeness. | M37: 8 | N37: — | O37: A.5.33 | P37: Sofia Kallio | Q37: 31 Mar 2027 | R37: W-09
A38: A.5.35 | B38: Independent review of information security | C38: Organisational | D38: Yes | E38: Annual PCI DSS assessment by an external QSA. SOC 2 Type II audit annually. Internal Audit reports independently to the Audit Committee. | F38: PCI AOC and SOC 2 report reviewed. Internal Audit 2026 plan inspected: no ISMS engagement. | G38: Partially implemented | I38: 2 | J38: Independent review covers PCI scope and SOC 2 criteria but has never covered the ISMS as a whole. No independent review of information security against ISO/IEC 27001 has been performed. | K38: P2 | L38: Add an ISMS review to the Internal Audit plan for 2027 covering Annex A and clauses 4 to 10. Define a review cycle so that the whole ISMS is covered over three years. | M38: 5 | N38: — | O38: 9.2 | P38: Faisal Rahman | Q38: 31 Mar 2027
A39: A.5.36 | B39: Compliance with policies, rules and standards for information security | C39: Organisational | D39: Yes | E39: Compliance is evidenced for PCI-scoped controls. Access recertification, patching SLAs and training completion are measured. | F39: Five compliance spreadsheets inspected. No version history, no approval records, 3 with conflicting content. | G39: Partially implemented | H39: Design deficient (no compliance monitoring calendar) and tooling inadequate | I39: 2 | J39: There is no systematic compliance monitoring across the whole control set. Policies, exceptions, risks and reviews are tracked across five uncontrolled spreadsheets, so compliance cannot be demonstrated on demand. | K39: P2 | L39: Procure and implement GRC tooling to hold policies, controls, exceptions, risks and evidence in one controlled system. Define a compliance monitoring calendar covering every applicable control. | M39: 20 | N39: 120000 | O39: — | P39: Chidi Eze | Q39: 31 Mar 2027 | R39: W-13
A40: A.5.37 | B40: Documented operating procedures | C40: Organisational | D40: Yes | E40: SOC runbooks and platform engineering procedures are documented and maintained. Procedures for corporate, finance and people processes are patchy. | F40: SOC and platform runbook repositories reviewed. Sample of 8 security-relevant processes outside engineering: 3 documented. | G40: Partially implemented | I40: 2 | J40: Documentation coverage is uneven. Several security-relevant operational activities outside engineering rely on individual knowledge rather than documented procedure. | K40: P3 | L40: Inventory security-relevant operating procedures across all functions. Document the gaps to a common template and place them under version control in the GRC platform. | M40: 18 | N40: — | O40: A.5.36 | P40: Sanjay Mehta | Q40: 30 Jun 2027 | R40: W-13
...

Sheet Clause Gaps
A1: Management System Requirements — clauses 4 to 10
A2: This is what certification is granted against. Annex A supports these requirements; it does not replace them.
A3: Clause | B3: Requirement | C3: Current state | D3: Evidence reviewed | E3: Status | F3: Gap description | G3: Priority | H3: Remediation action | I3: Effort (days) | J3: External cost (USD) | K3: Predecessor | L3: Owner | M3: Target date
A4: 4.1 | B4: Understanding the organisation and its context | C4: Business context is understood by management and reflected in strategy, but not documented for ISMS purposes. | D4: Interview: Head of Security Governance, CISO. No context documentation produced on request. | E4: Not implemented | F4: No documented determination of internal and external issues relevant to the ISMS. | G4: P1 | H4: Document the internal and external issues affecting the ISMS, including regulatory landscape, customer certification demands, growth rate and cloud dependency. Review annually. | I4: 4 | J4: — | K4: — | L4: Chidi Eze | M4: 31 Jan 2027
A5: 4.2 | B5: Understanding the needs and expectations of interested parties | C5: Requirements of customers, regulators and payment brands are tracked by Legal in the obligations register. | D5: Obligations register reviewed. No interested parties register exists. | E5: Partially implemented | F5: Interested parties and their information security requirements are not identified as an ISMS input; the obligations register serves a different purpose and omits parties such as investors and workers. | G5: P1 | H5: Produce an interested parties register mapping each party to its information security requirements and to the controls that satisfy them. | I5: 3 | J5: — | K5: 4.1 | L5: Chidi Eze | M5: 31 Jan 2027
A6: 4.3 | B6: Determining the scope of the information security management system | C6: A draft scope statement exists covering the three platforms, the AWS regions and both offices. | D6: Draft scope statement v0.3 reviewed, undated and unapproved. | E6: Partially implemented | F6: Scope is drafted but not approved, and cannot be finalised while approximately 40 SaaS applications remain unregistered and therefore unassessed for inclusion. | G6: P1 | H6: Complete the SaaS triage under A.5.23, then finalise and approve the scope statement at the ERC with documented boundaries and interfaces. | I6: 5 | J6: — | K6: A.5.23, A.5.9 | L6: Helen Achebe-Ward | M6: 31 Jan 2027
A7: 4.4 | B7: Information security management system | C7: Security controls operate effectively but are not organised or maintained as a management system. | D7: Assessment of the ISMS as a whole across this engagement. | E7: Not implemented | F7: The ISMS does not exist as an established, implemented and continually improved system. Processes and their interactions are not defined. | G7: P1 | H7: Establish the ISMS: define its processes, their sequence and interaction, and the criteria for their operation. This is the umbrella activity that the other clause gaps sit within. | I7: 12 | J7: — | K7: 4.1, 4.2, 4.3 | L7: Helen Achebe-Ward | M7: 31 Jan 2027
A8: 5.1 | B8: Leadership and commitment | C8: The ERC is genuinely engaged and the CEO chairs it. Security investment has been approved. | D8: ERC minutes Mar-Aug 2026 reviewed. Budget approval for the certification programme evidenced Jul 2026. | E8: Partially implemented | F8: Commitment is real but undocumented against ISMS requirements. No evidence that leadership ensures ISMS requirements are integrated into business processes or that resources are determined for the ISMS specifically. | G8: P1 | H8: Document leadership commitment in POL-05. Record ISMS resourcing decisions and integration requirements in ERC minutes. | I8: 3 | J8: — | K8: 5.2 | L8: Priya Raghunathan | M8: 31 Jan 2027
A9: 5.2 | B9: Policy | C9: Tier 2 policies are strong and current. No Tier 1 apex policy exists. | D9: Policy library index reviewed. No Tier 1 policy exists. | E9: Not implemented | F9: There is no information security policy that establishes the ISMS, states objectives, includes a commitment to satisfy applicable requirements and to continual improvement, and is communicated as such. | G9: P1 | H9: Draft and approve AFT-ISMS-POL-05 to satisfy clause 5.2 in full. Communicate to all workers and make available to interested parties. | I9: 8 | J9: — | K9: — | L9: Helen Achebe-Ward | M9: 31 Jan 2027
A10: 5.3 | B10: Organisational roles, responsibilities and authorities | C10: Security roles exist and are staffed. Responsibilities appear across individual policies. | D10: Role descriptions for the security function reviewed. No ISMS reporting responsibility assigned. | E10: Partially implemented | F10: ISMS conformance reporting responsibility is not assigned. No single accountable owner is documented for reporting ISMS performance to top management. | G10: P2 | H10: Assign and document ISMS responsibilities and authorities, including the person responsible for reporting ISMS performance to the ERC. | I10: 3 | J10: — | K10: 5.2 | L10: Helen Achebe-Ward | M10: 31 Mar 2027
A11: 6.1.1 | B11: Actions to address risks and opportunities | C11: Risks are discussed at the ERC and captured in a spreadsheet. | D11: Risk spreadsheet reviewed. No ISMS-level risks and opportunities documented. | E11: Not implemented | F11: No documented determination of the risks and opportunities that need to be addressed to give assurance the ISMS can achieve its intended outcomes. | G11: P1 | H11: Document risks and opportunities to the ISMS itself, distinct from information security risks, and the actions to address them. | I11: 4 | J11: — | K11: 4.4 | L11: Chidi Eze | M11: 31 Jan 2027
A12: 6.1.2 | B12: Information security risk assessment | C12: Risk is tracked in a spreadsheet maintained by the Head of Security Governance. Assessment is performed by judgement without a defined method. | D12: Risk spreadsheet reviewed (41 entries, last updated Jun 2026). No methodology document exists. | E12: Not implemented | F12: No documented risk assessment process defining risk acceptance criteria, criteria for performing assessments, risk identification method, or how consistent, valid and comparable results are ensured. | G12: P1 | H12: Define and document the risk assessment methodology, using the impact, likelihood and rating scales in AFT-CTX-01. Deliverable AFT-ISMS-RSK-01 will apply it. | I12: 12 | J12: 15000 | K12: 4.3 | L12: Chidi Eze | M12: 31 Jan 2027
A13: 6.1.3 | B13: Information security risk treatment | C13: Remediation happens but is not framed as risk treatment. Statement of Applicability exists only as draft v0.3. | D13: SoA draft v0.3 reviewed. No risk treatment plan exists. No risk owner approvals located. | E13: Not implemented | F13: No risk treatment process, no risk treatment plan, and no approved Statement of Applicability. Risk owners have not formally approved treatment plans or accepted residual risk. | G13: P1 | H13: Define the risk treatment process. Complete and approve the Statement of Applicability covering all 93 Annex A controls with inclusion or exclusion justification. Produce a risk treatment plan and obtain risk owner approval. | I13: 20 | J13: — | K13: 6.1.2, 8.2 | L13: Chidi Eze | M13: 31 Jan 2027
A14: 6.2 | B14: Information security objectives and planning to achieve them | C14: Security has departmental goals but no ISMS objectives. | D14: Security team OKRs reviewed. These are departmental goals, not ISMS objectives under clause 6.2. | E14: Not implemented | F14: No documented information security objectives that are measurable, monitored, communicated and updated, with plans stating what will be done, by whom, when and how results are evaluated. | G14: P1 | H14: Set measurable information security objectives aligned to risk appetite, with owners, timescales and evaluation method. Approve at the ERC and report progress quarterly. | I14: 5 | J14: — | K14: 5.2, 6.1.2 | L14: Helen Achebe-Ward | M14: 31 Jan 2027
A15: 6.3 | B15: Planning of changes | C15: Technical change is well controlled through the CAB. ISMS change is not. | D15: Interview: Head of Security Governance. No ISMS change process exists. | E15: Partially implemented | F15: Changes to the ISMS itself are not planned in a determined manner. | G15: P3 | H15: Define how ISMS changes are proposed, assessed and approved, and record them. | I15: 2 | J15: — | K15: 4.4 | L15: Chidi Eze | M15: 30 Jun 2027
A16: 7.1 | B16: Resources | C16: Security function is resourced with 14 staff and an approved budget. Certification programme funded. | D16: Organisation chart and approved budget reviewed. Security function headcount 14. | E16: Implemented
A17: 7.2 | B17: Competence | C17: Security staff hold relevant certifications. Training budget available. Competence is managed through normal performance processes. | D17: Certification records for the security team reviewed. No competence requirements documented for ISMS roles. | E17: Partially implemented | F17: Competence requirements for ISMS roles are not documented, and evidence of competence is not retained as documented information. | G17: P2 | H17: Define competence requirements for each ISMS role, assess current holders against them, and retain evidence. | I17: 6 | J17: — | K17: 5.3 | L17: Grace Lindberg | M17: 31 Mar 2027
A18: 7.3 | B18: Awareness | C18: Annual training at 91% completion. Policies communicated at onboarding. | D18: KnowBe4 completion report reviewed: 91.0%. Awareness of the policy not evidenced for the residual 9%. | E18: Partially implemented | F18: Awareness of the information security policy and of the implications of not conforming is not evidenced for the 9% who have not completed training, concentrated in Sales and London. | G18: P2 | H18: Close the completion gap to above 98% and evidence it. Deliver AFT-ISMS-PRG-01 with escalation for non-completion. | I18: 8 | J18: — | K18: A.6.3 | L18: Helen Achebe-Ward | M18: 31 Mar 2027
A19: 7.4 | B19: Communication | C19: Security communicates through Slack, all-hands and targeted briefings. Effective in practice. | D19: Interview: Director of Corporate Communications. No ISMS communication plan exists. | E19: Partially implemented | F19: Internal and external communications relevant to the ISMS are not determined: what, when, with whom and how is not documented. | G19: P3 | H19: Document an ISMS communication plan covering internal and external audiences, triggers and channels. | I19: 3 | J19: — | K19: 4.2 | L19: Nadia Haddad | M19: 30 Jun 2027
A20: 7.5 | B20: Documented information | C20: Policies are version controlled in Google Drive. Registers are held across five spreadsheets with no version control, no approval record and no retention rule. | D20: Five compliance spreadsheets inspected. Policy library version control confirmed adequate; registers not. | E20: Partially implemented | F20: Control of documented information is inadequate. Creation, update, approval, version control, distribution and retention are not consistently applied outside the policy set. | G20: P2 | H20: Implement GRC tooling as the controlled repository for ISMS documented information, with approval workflow, versioning and access control. | I20: 10 | J20: — | K20: A.5.36 | L20: Chidi Eze | M20: 31 Mar 2027
A21: 8.1 | B21: Operational planning and control | C21: Security operations run to defined runbooks in the SOC and platform teams. Coverage is patchy elsewhere. | D21: SOC and platform runbooks reviewed. Coverage assessed against the ISMS process set: incomplete. | E21: Partially implemented | F21: Processes needed to meet information security requirements are not all planned, implemented and controlled with retained documented information demonstrating they were carried out as planned. | G21: P2 | H21: Identify the ISMS operational processes, document them, and define the evidence each produces. | I21: 12 | J21: — | K21: 4.4 | L21: Chidi Eze | M21: 31 Mar 2027
A22: 8.2 | B22: Information security risk assessment (performance) | C22: No risk assessments have been performed to a defined methodology at planned intervals. | D22: No risk assessment records located at any interval. | E22: Not implemented | F22: Risk assessments are not performed at planned intervals or when significant changes occur, and results are not retained as documented information. | G22: P1 | H22: Perform the first full risk assessment under the new methodology (AFT-ISMS-RSK-01). Set a planned interval of at least annually and on significant change. | I22: 18 | J22: — | K22: 6.1.2 | L22: Chidi Eze | M22: 31 Jan 2027
A23: 8.3 | B23: Information security risk treatment (performance) | C23: Remediation is tracked but not as risk treatment against an approved plan. | D23: No risk treatment plan or implementation records located. | E23: Not implemented | F23: The risk treatment plan does not exist and therefore is not implemented, and results are not retained. | G23: P1 | H23: Produce the risk treatment plan from the risk assessment output, obtain risk owner approval, and track implementation to closure. | I23: 14 | J23: — | K23: 6.1.3 | L23: Chidi Eze | M23: 31 Jan 2027
A24: 9.1 | B24: Monitoring, measurement, analysis and evaluation | C24: Operational security metrics are produced monthly: patching SLA, access recertification, phishing results, incident volumes. | D24: Monthly security metrics pack reviewed (Jun-Aug 2026). Metrics measure activity, not ISMS effectiveness. | E24: Partially implemented | F24: Metrics measure activity, not ISMS effectiveness. What needs to be monitored, the methods, and when results are analysed and evaluated are not determined for the ISMS. | G24: P2 | H24: Define ISMS performance measures tied to the information security objectives, with methods, frequency and responsibility. Report to the ERC quarterly. | I24: 8 | J24: — | K24: 6.2 | L24: Chidi Eze | M24: 31 Mar 2027
A25: 9.2 | B25: Internal audit | C25: Internal Audit is independent, reports to the Audit Committee, and audits security topics within its annual plan. | D25: Internal Audit 2026 plan and charter reviewed. No ISMS audit programme exists. | E25: Partially implemented | F25: No internal audit programme covering the ISMS against ISO/IEC 27001 requirements exists. Audit criteria, scope, frequency and methods for the ISMS have not been defined. | G25: P1 | H25: Establish an ISMS internal audit programme covering all clauses and applicable Annex A controls across a defined cycle. Perform at least one full internal audit before the Stage 2 assessment. | I25: 25 | J25: 45000 | K25: 4.4, 8.2 | L25: Faisal Rahman | M25: 31 Jan 2027
A26: 9.3 | B26: Management review | C26: The ERC receives security reporting monthly and makes decisions on it. | D26: ERC minutes reviewed for clause 9.3 inputs. None of the required agenda items evidenced. | E26: Not implemented | F26: No management review is conducted against the clause 9.3 inputs: audit results, interested party feedback, risk assessment status, objectives performance, nonconformities and improvement opportunities. No management review records exist. | G26: P1 | H26: Establish a formal management review at least annually, with the clause 9.3 agenda, held at the ERC and minuted as documented information. | I26: 5 | J26: — | K26: 9.2, 9.1 | L26: Helen Achebe-Ward | M26: 31 Jan 2027
A27: 10.1 | B27: Continual improvement | C27: Improvement occurs through post-incident review actions and audit findings. | D27: Assessed across the engagement. Improvement occurs but is not demonstrable as ISMS improvement. | E27: Partially implemented | F27: Continual improvement of the suitability, adequacy and effectiveness of the ISMS is not demonstrable because the ISMS is not established. | G27: P2 | H27: Once the ISMS is established, evidence improvement through management review outputs, objective performance trends and closed corrective actions. | I27: 3 | J27: — | K27: 9.3 | L27: Helen Achebe-Ward | M27: 31 Mar 2027
A28: 10.2 | B28: Nonconformity and corrective action | C28: Incident post-incident reviews produce actions tracked to closure. Audit findings are tracked by Internal Audit. | D28: Post-incident review process reviewed. No ISMS nonconformity process exists. | E28: Partially implemented | F28: No ISMS nonconformity process exists. Root cause analysis, evaluation of whether similar nonconformities exist, and retention of records of the nature of nonconformities and subsequent actions are not defined for the ISMS. | G28: P2 | H28: Define a nonconformity and corrective action process covering identification, containment, root cause analysis, corrective action and effectiveness review. Hold records in the GRC platform. | I28: 6 | J28: — | K28: 4.4 | L28: Chidi Eze | M28: 31 Mar 2027

Sheet Remediation Plan
A1: Remediation Plan
A2: Gaps grouped into delivery workstreams. Status column is for the programme to maintain.
A3: Workstream / Ref | B3: Item | C3: Priority | D3: Action | E3: Effort (days) | F3: External cost | G3: Predecessor | H3: Owner | I3: Target date | J3: Status | K3: Notes
A4: WS1 — Establish the management system | B4: Lead: Chidi Eze — The clause 4-10 build. Without this there is nothing to certify.
A5: 4.1 | B5: Understanding the organisation and its context | C5: P1 | D5: Document the internal and external issues affecting the ISMS, including regulatory landscape, customer certification demands, growth rate and cloud dependency. Review annually. | E5: 4 | F5: — | G5: — | H5: Chidi Eze | I5: 31 Jan 2027 | J5: Not started
A6: 4.2 | B6: Understanding the needs and expectations of interested parties | C6: P1 | D6: Produce an interested parties register mapping each party to its information security requirements and to the controls that satisfy them. | E6: 3 | F6: — | G6: 4.1 | H6: Chidi Eze | I6: 31 Jan 2027 | J6: Not started
A7: 4.3 | B7: Determining the scope of the information security management system | C7: P1 | D7: Complete the SaaS triage under A.5.23, then finalise and approve the scope statement at the ERC with documented boundaries and interfaces. | E7: 5 | F7: — | G7: A.5.23, A.5.9 | H7: Chidi Eze | I7: 31 Jan 2027 | J7: Not started
A8: 4.4 | B8: Information security management system | C8: P1 | D8: Establish the ISMS: define its processes, their sequence and interaction, and the criteria for their operation. This is the umbrella activity that the other clause gaps sit within. | E8: 12 | F8: — | G8: 4.1, 4.2, 4.3 | H8: Chidi Eze | I8: 31 Jan 2027 | J8: Not started
A9: 5.1 | B9: Leadership and commitment | C9: P1 | D9: Document leadership commitment in POL-05. Record ISMS resourcing decisions and integration requirements in ERC minutes. | E9: 3 | F9: — | G9: 5.2 | H9: Chidi Eze | I9: 31 Jan 2027 | J9: Not started
A10: 5.2 | B10: Policy | C10: P1 | D10: Draft and approve AFT-ISMS-POL-05 to satisfy clause 5.2 in full. Communicate to all workers and make available to interested parties. | E10: 8 | F10: — | G10: — | H10: Chidi Eze | I10: 31 Jan 2027 | J10: Not started
A11: 5.3 | B11: Organisational roles, responsibilities and authorities | C11: P2 | D11: Assign and document ISMS responsibilities and authorities, including the person responsible for reporting ISMS performance to the ERC. | E11: 3 | F11: — | G11: 5.2 | H11: Chidi Eze | I11: 31 Mar 2027 | J11: Not started
A12: 6.1.1 | B12: Actions to address risks and opportunities | C12: P1 | D12: Document risks and opportunities to the ISMS itself, distinct from information security risks, and the actions to address them. | E12: 4 | F12: — | G12: 4.4 | H12: Chidi Eze | I12: 31 Jan 2027 | J12: Not started
A13: 6.1.2 | B13: Information security risk assessment | C13: P1 | D13: Define and document the risk assessment methodology, using the impact, likelihood and rating scales in AFT-CTX-01. Deliverable AFT-ISMS-RSK-01 will apply it. | E13: 12 | F13: 15000 | G13: 4.3 | H13: Chidi Eze | I13: 31 Jan 2027 | J13: Not started
A14: 6.1.3 | B14: Information security risk treatment | C14: P1 | D14: Define the risk treatment process. Complete and approve the Statement of Applicability covering all 93 Annex A controls with inclusion or exclusion justification. Produce a risk treatment plan and obtain risk owner approval. | E14: 20 | F14: — | G14: 6.1.2, 8.2 | H14: Chidi Eze | I14: 31 Jan 2027 | J14: Not started
A15: 6.2 | B15: Information security objectives and planning to achieve them | C15: P1 | D15: Set measurable information security objectives aligned to risk appetite, with owners, timescales and evaluation method. Approve at the ERC and report progress quarterly. | E15: 5 | F15: — | G15: 5.2, 6.1.2 | H15: Chidi Eze | I15: 31 Jan 2027 | J15: Not started
A16: 6.3 | B16: Planning of changes | C16: P3 | D16: Define how ISMS changes are proposed, assessed and approved, and record them. | E16: 2 | F16: — | G16: 4.4 | H16: Chidi Eze | I16: 30 Jun 2027 | J16: Not started
A17: 7.2 | B17: Competence | C17: P2 | D17: Define competence requirements for each ISMS role, assess current holders against them, and retain evidence. | E17: 6 | F17: — | G17: 5.3 | H17: Chidi Eze | I17: 31 Mar 2027 | J17: Not started
A18: 7.4 | B18: Communication | C18: P3 | D18: Document an ISMS communication plan covering internal and external audiences, triggers and channels. | E18: 3 | F18: — | G18: 4.2 | H18: Chidi Eze | I18: 30 Jun 2027 | J18: Not started
A19: 7.5 | B19: Documented information | C19: P2 | D19: Implement GRC tooling as the controlled repository for ISMS documented information, with approval workflow, versioning and access control. | E19: 10 | F19: — | G19: A.5.36 | H19: Chidi Eze | I19: 31 Mar 2027 | J19: Not started
A20: 8.1 | B20: Operational planning and control | C20: P2 | D20: Identify the ISMS operational processes, document them, and define the evidence each produces. | E20: 12 | F20: — | G20: 4.4 | H20: Chidi Eze | I20: 31 Mar 2027 | J20: Not started
A21: 8.2 | B21: Information security risk assessment (performance) | C21: P1 | D21: Perform the first full risk assessment under the new methodology (AFT-ISMS-RSK-01). Set a planned interval of at least annually and on significant change. | E21: 18 | F21: — | G21: 6.1.2 | H21: Chidi Eze | I21: 31 Jan 2027 | J21: Not started
A22: 8.3 | B22: Information security risk treatment (performance) | C22: P1 | D22: Produce the risk treatment plan from the risk assessment output, obtain risk owner approval, and track implementation to closure. | E22: 14 | F22: — | G22: 6.1.3 | H22: Chidi Eze | I22: 31 Jan 2027 | J22: Not started
A23: 9.1 | B23: Monitoring, measurement, analysis and evaluation | C23: P2 | D23: Define ISMS performance measures tied to the information security objectives, with methods, frequency and responsibility. Report to the ERC quarterly. | E23: 8 | F23: — | G23: 6.2 | H23: Chidi Eze | I23: 31 Mar 2027 | J23: Not started
A24: 9.2 | B24: Internal audit | C24: P1 | D24: Establish an ISMS internal audit programme covering all clauses and applicable Annex A controls across a defined cycle. Perform at least one full internal audit before the Stage 2 assessment. | E24: 25 | F24: 45000 | G24: 4.4, 8.2 | H24: Chidi Eze | I24: 31 Jan 2027 | J24: Not started
A25: 9.3 | B25: Management review | C25: P1 | D25: Establish a formal management review at least annually, with the clause 9.3 agenda, held at the ERC and minuted as documented information. | E25: 5 | F25: — | G25: 9.2, 9.1 | H25: Chidi Eze | I25: 31 Jan 2027 | J25: Not started
A26: 10.1 | B26: Continual improvement | C26: P2 | D26: Once the ISMS is established, evidence improvement through management review outputs, objective performance trends and closed corrective actions. | E26: 3 | F26: — | G26: 9.3 | H26: Chidi Eze | I26: 31 Mar 2027 | J26: Not started
A27: 10.2 | B27: Nonconformity and corrective action | C27: P2 | D27: Define a nonconformity and corrective action process covering identification, containment, root cause analysis, corrective action and effectiveness review. Hold records in the GRC platform. | E27: 6 | F27: — | G27: 4.4 | H27: Chidi Eze | I27: 31 Mar 2027 | J27: Not started
A28: A.5.1 | B28: Policies for information security | C28: P1 | D28: Draft, approve and publish AFT-ISMS-POL-05 Information Security Policy at Tier 1, signed by the CEO. Map every Tier 2 policy and standard to it and to the SoA. Establish an annual policy review calendar. | E28: 8 | F28: — | G28: — | H28: Chidi Eze | I28: 31 Jan 2027 | J28: Not started
A29: A.5.2 | B29: Information security roles and responsibilities | C29: P2 | D29: Produce a single ISMS roles and responsibilities matrix covering all Annex A control owners and clause responsibilities. Ratify at the Executive Risk Committee and reference it from POL-05. | E29: 6 | F29: — | G29: 5.2 | H29: Chidi Eze | I29: 31 Mar 2027 | J29: Not started
A30: A.5.4 | B30: Management responsibilities | C30: P2 | D30: Document management responsibilities in POL-05. Add a standing ISMS agenda item to the ERC with recorded decisions and actions. | E30: 3 | F30: — | G30: 5.2 | H30: Chidi Eze | I30: 31 Mar 2027 | J30: Not started
A32: WS2 — Asset and cloud scope integrity | B32: Lead: Claire Bennett — The SaaS estate must be known before scope can be approved or risk assessed.
A33: A.5.9 | B33: Inventory of information and other associated assets | C33: P1 | D33: Reconcile the CASB discovery output against the asset register. Assign an owner and classification to every application, or decommission it. Establish monthly CASB-to-register reconciliation as a standing control. | E33: 30 | F33: — | G33: — | H33: Claire Bennett | I33: 31 Jan 2027 | J33: Not started
A34: A.5.23 | B34: Information security for use of cloud services | C34: P1 | D34: Triage the 40 discovered applications by data classification. Block or sanction each one. Route SaaS procurement through Okta and Procurement so that acquisition without assessment is not technically possible. | E34: 25 | F34: 30000 | G34: A.5.9 | H34: Claire Bennett | I34: 31 Jan 2027 | J34: Not started
A35: A.5.32 | B35: Intellectual property rights | C35: P3 | D35: Include licence compliance in the SaaS triage exercise under A.5.23. Establish a software asset management process covering acquisition and true-up. | E35: 5 | F35: — | G35: A.5.23 | H35: Claire Bennett | I35: 30 Jun 2027 | J35: Not started
