Workbook

Sheet Cover & Method
A1: Third-Party Risk Assessment
A2: Aldridge Financial Technologies | AFT-TPRM-ASM-01 | Version 2.1 | 9 September 2026 | Classification: Confidential
A5: ENGAGEMENT
A6: Purpose | B6: Assessment of three suppliers against the Aldridge third-party security questionnaire, producing a scored risk rating and a remediation position for each. Conducted under AFT-ISMS-POL-09.
A7: Suppliers assessed | B7: V-01 Northgate Analytics Ltd · V-02 Verrio Cloud Services, Inc. · V-03 Meridian BPO Solutions
A8: Trigger | B8: Scheduled reassessment. V-01 and V-03 were overdue against the annual obligation in POL-09, forming part of the backlog recorded at W-08.
A9: Assessment date | B9: September 2026
A10: Assessed by | B10: Procurement (Elena Petrova) with Security Governance (Chidi Eze)
A11: Basis | B11: Questionnaire response, evidence review, and follow-up interview. Findings recorded where the assessment identified matters not disclosed in the written response.
A12: Inputs | B12: AFT-CTX-01 Organisation Context Pack v1.2; AFT-ISMS-RSK-01 risk register v1.0; AFT-ISMS-GAP-01 gap analysis v1.0; supplier contracts and evidence packs.
A14: RECONCILIATION TO THE RISK REGISTER
B15: Supplier exposures were already assessed in AFT-ISMS-RSK-01 and are not restated here at different values. R-07 Northgate compromise (residual 15, High); R-08 Northgate outage (residual 8, Moderate); R-09 undisclosed fourth parties (residual 12, High); R-10 Meridian insider exfiltration (residual 12, High). The ratings produced by this assessment are consistent with those residuals. Where this assessment identifies a new exposure, it is raised as a finding and referred for addition to the risk register rather than scored twice.
A17: CHANGES IN VERSION 2.0
B18: Two domains added following expert review: D12 Financial viability and business resilience, and D13 Continuous monitoring and ongoing assurance. Both were absent from version 1.0 and both produced material findings.
B19: Service-model weighting profiles introduced. Version 1.0 applied one weighting to three suppliers with incomparable service models, which scored an offshore contact centre on secure development lifecycle at the same weight as a software provider. Each supplier is now weighted against the profile appropriate to what it actually does. Weights total 100 in every profile, so scores remain comparable across the estate.
B20: An evidence log has been added recording what was reviewed, when, by whom, and what was requested and not provided. A portfolio concentration analysis has been added, which a supplier-by-supplier assessment cannot produce.
A22: SCORING MODEL
B23: Each of 65 questions is scored 0 to 4. A domain score is the mean of its question scores. The overall score is the sum across 13 domains of (domain weight x domain mean / 4), producing a result on a 0 to 100 scale. Weights are drawn from the service-model profile assigned to the supplier and total 100 in every profile.
A24: 4 — Strong | B24: Control evidenced and independently assured.
A25: 3 — Adequate | B25: Control evidenced, self-attested.
A26: 2 — Developing | B26: Control partially in place.
A27: 1 — Weak | B27: Control asserted but unevidenced.
A28: 0 — Absent | B28: No control, or refused to answer.
A30: RATING BANDS (AFT-CTX-01 s9.3)
A31: 85–100 Low risk | B31: Approve. Standard reassessment cycle.
A32: 70–84 Moderate risk | B32: Approve with conditions. Remediation plan agreed.
A33: 50–69 High risk | B33: Approve only with ERC sign-off, compensating controls and a dated remediation plan.
A34: 0–49 Critical risk | B34: Do not approve, or terminate. Exit plan required.
A36: AUTOMATIC ESCALATION
B37: A critical finding in any of four areas escalates the rating one band worse regardless of score: encryption of Restricted data, access control, incident notification commitment, or subcontractor disclosure. The escalation is applied by formula on the Results tab and is visible in the calculation, not applied silently.
A39: LIMITATIONS
B40: This is an assessment, not an audit. Evidence was reviewed as presented; no independent testing of supplier controls was performed and no site visit was conducted. Scores reflect the position disclosed and evidenced at the assessment date. Where a supplier's written response was contradicted by evidence reviewed later in the assessment, the finding is recorded and the score reflects the corrected position — see V-01 question 11.1 and V-03 question 3.5.

Sheet Vendor Profiles
A1: Suppliers Assessed
A2: Tiering per AFT-CTX-01 s9.1. All three suppliers are fictional.
A4: Supplier ID | B4: V-01 | C4: V-02 | D4: V-03
A5: Name | B5: Northgate Analytics Ltd | C5: Verrio Cloud Services, Inc. | D5: Meridian BPO Solutions
A6: Location | B6: London, United Kingdom | C6: Denver, Colorado, United States | D6: Manila, Philippines
A7: Service provided | B7: Machine-learning fraud scoring and risk decisioning, called synchronously in the payment authorisation path | C7: Document generation and electronic signature for loan agreements and regulatory disclosures | D7: Outsourced customer support and payment dispute handling, tier 1 and tier 2
A8: Data accessed | B8: Cardholder data (truncated PAN and BIN), transaction metadata, merchant data | C8: Borrower personal data, credit decision output, executed agreements | D8: Customer personal data, partial account data, dispute correspondence; Restricted on escalation
A9: Highest classification | B9: Restricted | C9: Restricted | D9: Confidential / Restricted on escalation
A10: Tier | B10: Tier 1 — Critical | C10: Tier 2 — High | D10: Tier 2 — High
A11: Last assessed | B11: October 2024 (23 months overdue) | C11: March 2026 (current) | D11: August 2025 (13 months, overdue)
A12: Contract position | B12: Pre-2023 master agreement; current security schedule NOT incorporated | C12: 2024 agreement; current security schedule incorporated | D12: 2023 agreement; security schedule incorporated but weaker notification terms negotiated
A13: Linked risks (AFT-ISMS-RSK-01) | B13: R-07 (residual 15, High), R-08 (residual 8, Moderate), R-09 (residual 12, High) | C13: None assessed separately; contributes to the general supplier risk position | D13: R-10 (residual 12, High)

Sheet Questionnaire & Scores
A1: Assessment Questionnaire and Scored Responses
A2: 65 questions across 13 domains. Score cells drive every figure on the Results tab. Domain weights vary by service-model profile — see Results.
A3: Domain | B3: Ref | C3: Question | D3: Evidence expected | E3: V-01 score | F3: V-01 response and assessor note | G3: V-02 score | H3: V-02 response and assessor note | I3: V-03 score | J3: V-03 response and assessor note
A4: D1 — Governance, risk and compliance
A5: D1 | B5: 1.1 | C5: Do you hold a current, independently assured information security certification covering the services provided to Aldridge? | D5: ISO/IEC 27001 certificate with scope statement, or SOC 2 Type II report | E5: 4 | F5: ISO/IEC 27001:2022 certified; certificate provided, scope covers the decisioning platform. Valid to March 2028. | G5: 4 | H5: ISO/IEC 27001:2022 certified and SOC 2 Type II report for the period to 31 March 2026 provided. | I5: 3 | J5: Not certified. ISO/IEC 27001 implementation programme underway with a stated target of Q4 2027; gap analysis provided as evidence.
A6: D1 | B6: 1.2 | C6: Is there a documented information security policy set, approved by executive management and reviewed at least annually? | D6: Policy index with approval and review dates | E6: 4 | F6: Full policy set provided with board approval and current review dates. | G6: 4 | H6: Policy set provided, annual review evidenced, CISO-owned. | I6: 2 | J6: Policies exist but three of nine are past their stated review date; approval recorded at operations director level, not executive.
A7: D1 | B7: 1.3 | C7: Is there a named individual accountable for information security, with a reporting line independent of service delivery? | D7: Organisation chart and role description | E7: 4 | F7: CISO reports to the CEO. Security team of 11. | G7: 4 | H7: VP Security reports to the CTO with a dotted line to the audit committee. | I7: 2 | J7: Information Security Manager reports to the Head of Operations, who also owns delivery targets. No independent escalation route.
A8: D1 | B8: 1.4 | C8: Do you perform a documented information security risk assessment at least annually? | D8: Risk assessment methodology and most recent register extract | E8: 3 | F8: Annual assessment performed; methodology provided. Register extract redacted more heavily than requested. | G8: 4 | H8: Annual assessment with quarterly review; methodology and register extract provided in full. | I8: 2 | J8: Risk register maintained but no documented methodology; last full review March 2025.
A9: D1 | B9: 1.5 | C9: Do you permit customer audit or assessment of the services provided, and has such an assessment been performed in the last 24 months? | D9: Audit rights clause and evidence of a completed customer assessment | E9: 3 | F9: Audit rights offered in current standard terms. Aldridge holds a pre-2023 contract that does not contain them; Northgate confirmed willingness to grant them by amendment. | G9: 3 | H9: Audit rights present in contract; no customer audit performed in period, remote assessment offered. | I9: 2 | J9: Audit rights present but limited to a shared annual assessment report; site visit requires 90 days notice and is at Meridian's discretion.
A10: D2 — Access control and identity management | C10: Automatic escalation area: Access control
A11: D2 | B11: 2.1 | C11: Is multi-factor authentication enforced for all personnel accessing systems that process customer data? | D11: Configuration evidence or policy plus enforcement screenshot | E11: 4 | F11: MFA enforced across all staff; FIDO2 for administrative roles. | G11: 4 | H11: MFA enforced universally; hardware tokens for privileged access. | I11: 0 | J11: CRITICAL FINDING. No MFA on the agent servicing portal, which is the interface used to access Aldridge customer data. Password-only authentication for approximately 40 agents. MFA is enforced for corporate email but not for the delivery environment.
A12: D2 | B12: 2.2 | C12: Are access rights granted on a least-privilege basis and formally approved before provisioning? | D12: Access request and approval workflow evidence | E12: 4 | F12: Role-based provisioning through an identity platform with manager and system owner approval. | G12: 4 | H12: Role-based with documented approval; joiner workflow integrated with HR. | I12: 2 | J12: Access granted by team leader request via email. No system owner approval step. Role definitions exist but individual grants outside role are common.
A13: D2 | B13: 2.3 | C13: Are access rights reviewed and recertified at least quarterly for systems processing customer data? | D13: Two most recent recertification campaign records | E13: 3 | F13: Recertification performed semi-annually, not quarterly. Records provided for both 2026 cycles. | G13: 4 | H13: Quarterly recertification evidenced with revocation counts. | I13: 2 | J13: Annual review only. Most recent completed February 2026; 14 accounts revoked, indicating material drift between cycles.
A14: D2 | B14: 2.4 | C14: Is privileged access separately controlled, time-bound and session-logged? | D14: PAM configuration or equivalent control evidence | E14: 3 | F14: Administrative access separated with approval workflow; sessions logged but not recorded. No just-in-time expiry. | G14: 4 | H14: Privileged access brokered, time-bound to 8 hours, sessions recorded. | I14: 2 | J14: Administrator accounts are standing and shared between two named individuals for the servicing platform.
A15: D2 | B15: 2.5 | C15: Is access revoked within a defined period on termination, and is that period evidenced? | D15: Leaver procedure and sample revocation records | E15: 3 | F15: Revocation within one business day per procedure; sample records confirm compliance. | G15: 3 | H15: Revocation within 24 hours; sampled records confirm. | I15: 2 | J15: Procedure states 48 hours. Sample of five leavers showed one account active 9 days after departure.
A16: D3 — Data protection and cryptography | C16: Automatic escalation area: Encryption of Restricted data
A17: D3 | B17: 3.1 | C17: Is Aldridge data encrypted at rest using an industry-accepted algorithm, with documented key management? | D17: Encryption standard and key management procedure | E17: 4 | F17: AES-256 at rest; keys in a managed HSM-backed service with documented rotation. | G17: 4 | H17: AES-256 at rest with customer-scoped keys; rotation annually and on personnel change. | I17: 2 | J17: Case management database encrypted at rest by platform default. Key management is the hosting provider's; Meridian could not describe rotation.
A18: D3 | B18: 3.2 | C18: Is Aldridge data encrypted in transit, including on internal network segments? | D18: TLS configuration evidence | E18: 4 | F18: TLS 1.3 externally, TLS 1.2 minimum internally; mutual TLS on the Aldridge integration. | G18: 4 | H18: TLS 1.3 externally and internally; certificate management automated. | I18: 3 | J18: TLS 1.2 externally. Internal traffic between the agent desktop layer and the case database is unencrypted within the delivery centre VLAN.
A19: D3 | B19: 3.3 | C19: Is Aldridge data logically or physically segregated from that of other customers? | D19: Architecture description or tenancy model | E19: 3 | F19: Logical segregation by tenant identifier in a shared database. Segregation testing performed but not independently validated. | G19: 4 | H19: Separate database schema per customer with enforced row-level isolation; independently tested. | I19: 2 | J19: Shared case management instance with role-based filtering. Agents supporting multiple clients can, by misconfiguration, view records outside their assignment; one such incident occurred in 2025.
A20: D3 | B20: 3.4 | C20: Are documented data retention and secure deletion practices applied to Aldridge data? | D20: Retention schedule and deletion evidence | E20: 3 | F20: Retention of 24 months for scoring inputs, documented. Deletion certificate process exists but has not been exercised for Aldridge data. | G20: 4 | H20: Retention configured per customer contract; deletion evidenced with certificates on prior customer offboarding. | I20: 2 | J20: Retention stated as 'per client instruction' but no configuration enforces it. Case records from 2021 remain in the live system.
A21: D3 | B21: 3.5 | C21: Where is Aldridge data stored and processed, and are all locations disclosed? | D21: Data residency statement covering all processing locations | E21: 3 | F21: Primary processing in UK. Model training uses an aggregated dataset processed in a US region — disclosed only on direct questioning during this assessment, not in the original response. | G21: 3 | H21: US processing only; residency statement provided. No UK region available, which constrains future UK expansion. | I21: 2 | J21: Manila primary. Overflow capacity is handled from a second site in Cebu that was not disclosed in the questionnaire response and was identified from the business continuity plan.
A22: D4 — Secure development and change management
A23: D4 | B23: 4.1 | C23: Is there a documented secure development lifecycle covering design, code review and testing? | D23: SDLC documentation | E23: 4 | F23: Documented SDLC with mandatory peer review and security sign-off at design. | G23: 4 | H23: Documented SDLC with threat modelling at design stage. | I23: 3 | J23: Configuration-led rather than development-led; changes to the case platform follow a documented change process.
A24: D4 | B24: 4.2 | C24: Is static and dependency analysis performed automatically as part of the build? | D24: Pipeline configuration and a sample report | E24: 3 | F24: SAST and SCA in CI. Findings triaged but no blocking threshold — high severity issues can merge. | G24: 4 | H24: SAST, DAST and SCA with blocking thresholds; sample report provided. | I24: 3 | J24: Not applicable to development, but vendor-supplied platform patches are tested before deployment.
A25: D4 | B25: 4.3 | C25: Are development, test and production environments separated, and is production data excluded from lower environments? | D25: Environment architecture and data handling statement | E25: 3 | F25: Environments separated. Anonymised production-derived data is used in test; anonymisation method described but not independently validated. | G25: 4 | H25: Environments fully separated; synthetic data only in lower environments. | I25: 2 | J25: A test instance of the case platform contains a 2024 copy of live case data including customer records.
A26: D4 | B26: 4.4 | C26: Are changes to production formally approved and recorded? | D26: Change management procedure and sample records | E26: 3 | F26: CAB process with recorded approvals; emergency changes reconciled retrospectively. | G26: 3 | H26: Change process with approval records; sample provided. | I26: 2 | J26: Change log maintained in a spreadsheet; three of ten sampled changes had no recorded approver.
A27: D4 | B27: 4.5 | C27: Is a documented rollback capability maintained for production changes? | D27: Rollback procedure evidence | E27: 3 | F27: Rollback documented and exercised during 2026. | G27: 3 | H27: Blue-green deployment with automated rollback. | I27: 2 | J27: Rollback relies on the platform vendor's support process; not exercised.
A28: D5 — Infrastructure and network security
A29: D5 | B29: 5.1 | C29: Is the infrastructure hosting Aldridge data segmented from corporate and other environments? | D29: Network architecture diagram | E29: 4 | F29: Production segregated into a dedicated cloud account with no path to corporate. | G29: 4 | H29: Production isolated per environment with enforced boundaries. | I29: 3 | J29: Delivery centre network segmented from corporate by VLAN; segmentation not tested.
A30: D5 | B30: 5.2 | C30: Are systems hardened to a documented baseline? | D30: Hardening standard and compliance evidence | E30: 4 | F30: CIS benchmarks applied with automated compliance scanning. | G30: 4 | H30: CIS Level 1 with continuous posture monitoring. | I30: 2 | J30: Standard build image used; no documented baseline or compliance scanning.
A31: D5 | B31: 5.3 | C31: Are endpoints used to access Aldridge data managed, encrypted and protected by endpoint detection? | D31: Device management and EDR coverage evidence | E31: 3 | F31: Managed endpoints with disk encryption and EDR at 97% coverage. | G31: 4 | H31: Fully managed fleet, encryption and EDR at 100%, evidenced. | I31: 2 | J31: Agent workstations are locked-down thin clients with no local storage, which is a genuine strength. However there is no endpoint detection capability, and supervisor laptops with local storage are outside the thin client estate.
A32: D5 | B32: 5.4 | C32: Are physical access controls in place at facilities where Aldridge data is handled? | D32: Physical security description and access control evidence | E32: 3 | F32: Cloud-hosted; inherits provider controls. Office access badge-controlled. | G32: 3 | H32: Cloud-hosted; office access controlled and logged. | I32: 4 | J32: Strong. Clean-desk delivery floor, no personal devices, no phones, no writing materials, biometric entry, CCTV with 90-day retention, bag search on exit. The best-controlled aspect of this supplier.
A33: D5 | B33: 5.5 | C33: Is remote access to environments processing Aldridge data restricted and monitored? | D33: Remote access policy and control evidence | E33: 3 | F33: VPN with MFA for engineering access; not zero trust. | G33: 3 | H33: VPN with MFA and device posture checks. | I33: 0 | J33: Home working was permitted for 12 agents during 2025 and remains technically possible. Remote sessions bypass the delivery centre physical controls entirely, and no compensating technical control was introduced.
A34: D6 — Vulnerability and patch management
A35: D6 | B35: 6.1 | C35: Are vulnerability scans performed at least monthly across the estate? | D35: Scan schedule and recent report | E35: 4 | F35: Weekly authenticated scanning; report provided. | G35: 4 | H35: Continuous scanning with posture management. | I35: 3 | J35: Monthly external scanning by a third party; internal scanning not performed.
A36: D6 | B36: 6.2 | C36: Are remediation timescales defined by severity, and are they met? | D36: SLA definition and compliance metrics | E36: 3 | F36: SLAs defined; critical within 14 days. Compliance reported at 88%. | G36: 4 | H36: SLAs defined and met at 97%, evidenced monthly. | I36: 2 | J36: No defined SLAs. Patching follows the platform vendor's release cycle.
A37: D6 | B37: 6.3 | C37: Is an independent penetration test performed at least annually, with findings remediated? | D37: Test report summary and remediation evidence | E37: 3 | F37: Annual test by a CREST-accredited firm; June 2026 report summary provided. Two medium findings remain open. | G37: 4 | H37: Annual test with all findings closed; retest evidence provided. | I37: 2 | J37: Last penetration test October 2023. None performed since.
A38: D6 | B38: 6.4 | C38: Is patching of operating systems and third-party software performed to a defined schedule? | D38: Patch management procedure and compliance data | E38: 3 | F38: Monthly patch cycle with emergency path; compliance at 94%. | G38: 3 | H38: Monthly cycle with automated deployment; compliance at 96%. | I38: 2 | J38: Patching performed quarterly on the thin client estate; two systems observed running an unsupported operating system version.
A39: D6 | B39: 6.5 | C39: Is there a process to assess and respond to newly disclosed critical vulnerabilities within days? | D39: Emergency vulnerability response procedure | E39: 3 | F39: Documented emergency response process invoked twice in 2026. | G39: 3 | H39: Documented and exercised; evidence provided for a 2026 critical CVE. | I39: 2 | J39: Reactive; depends on notification from the platform vendor.
A40: D7 — Logging, monitoring and detection
...

Sheet Results & Ratings
A1: Domain Scores, Weighted Result and Rating
A2: Every figure is a formula reading the Questionnaire & Scores tab. Escalation is applied in the open, not silently.
A4: Profiles applied: V-01 SaaS — Critical path | V-02 SaaS — Standard | V-03 Human services / BPO
A5: Domain | B5: V-01 weight | C5: V-01 mean | D5: V-01 wtd | E5: V-02 weight | F5: V-02 mean | G5: V-02 wtd | H5: V-03 weight | I5: V-03 mean | J5: V-03 wtd
A6: D1 — Governance, risk and compliance | B6: 0.08 | C6: =AVERAGE('Questionnaire & Scores'!E5:E9) -> 3.6 | D6: =B6*100*C6/4 -> 7.2 | E6: 0.09 | F6: =AVERAGE('Questionnaire & Scores'!G5:G9) -> 3.8 | G6: =E6*100*F6/4 -> 8.55 | H6: 0.08 | I6: =AVERAGE('Questionnaire & Scores'!I5:I9) -> 2.2 | J6: =H6*100*I6/4 -> 4.4
A7: D2 — Access control and identity management | B7: 0.11 | C7: =AVERAGE('Questionnaire & Scores'!E11:E15) -> 3.4 | D7: =B7*100*C7/4 -> 9.35 | E7: 0.11 | F7: =AVERAGE('Questionnaire & Scores'!G11:G15) -> 3.8 | G7: =E7*100*F7/4 -> 10.45 | H7: 0.14 | I7: =AVERAGE('Questionnaire & Scores'!I11:I15) -> 1.6 | J7: =H7*100*I7/4 -> 5.6
A8: D3 — Data protection and cryptography | B8: 0.14 | C8: =AVERAGE('Questionnaire & Scores'!E17:E21) -> 3.4 | D8: =B8*100*C8/4 -> 11.9 | E8: 0.15 | F8: =AVERAGE('Questionnaire & Scores'!G17:G21) -> 3.8 | G8: =E8*100*F8/4 -> 14.25 | H8: 0.13 | I8: =AVERAGE('Questionnaire & Scores'!I17:I21) -> 2.2 | J8: =H8*100*I8/4 -> 7.15
A9: D4 — Secure development and change management | B9: 0.07 | C9: =AVERAGE('Questionnaire & Scores'!E23:E27) -> 3.2 | D9: =B9*100*C9/4 -> 5.6 | E9: 0.08 | F9: =AVERAGE('Questionnaire & Scores'!G23:G27) -> 3.6 | G9: =E9*100*F9/4 -> 7.2 | H9: 0.02 | I9: =AVERAGE('Questionnaire & Scores'!I23:I27) -> 2.4 | J9: =H9*100*I9/4 -> 1.2
A10: D5 — Infrastructure and network security | B10: 0.09 | C10: =AVERAGE('Questionnaire & Scores'!E29:E33) -> 3.4 | D10: =B10*100*C10/4 -> 7.65 | E10: 0.09 | F10: =AVERAGE('Questionnaire & Scores'!G29:G33) -> 3.6 | G10: =E10*100*F10/4 -> 8.1 | H10: 0.1 | I10: =AVERAGE('Questionnaire & Scores'!I29:I33) -> 2.2 | J10: =H10*100*I10/4 -> 5.5
A11: D6 — Vulnerability and patch management | B11: 0.08 | C11: =AVERAGE('Questionnaire & Scores'!E35:E39) -> 3.2 | D11: =B11*100*C11/4 -> 6.4 | E11: 0.08 | F11: =AVERAGE('Questionnaire & Scores'!G35:G39) -> 3.6 | G11: =E11*100*F11/4 -> 7.2 | H11: 0.05 | I11: =AVERAGE('Questionnaire & Scores'!I35:I39) -> 2.2 | J11: =H11*100*I11/4 -> 2.75
A12: D7 — Logging, monitoring and detection | B12: 0.08 | C12: =AVERAGE('Questionnaire & Scores'!E41:E45) -> 3 | D12: =B12*100*C12/4 -> 6 | E12: 0.07 | F12: =AVERAGE('Questionnaire & Scores'!G41:G45) -> 3.4 | G12: =E12*100*F12/4 -> 5.95 | H12: 0.1 | I12: =AVERAGE('Questionnaire & Scores'!I41:I45) -> 1.8 | J12: =H12*100*I12/4 -> 4.5
A13: D8 — Incident response and breach notification | B13: 0.12 | C13: =AVERAGE('Questionnaire & Scores'!E47:E51) -> 2.2 | D13: =B13*100*C13/4 -> 6.6 | E13: 0.1 | F13: =AVERAGE('Questionnaire & Scores'!G47:G51) -> 3.6 | G13: =E13*100*F13/4 -> 9 | H13: 0.11 | I13: =AVERAGE('Questionnaire & Scores'!I47:I51) -> 2 | J13: =H13*100*I13/4 -> 5.5
A14: D9 — Business continuity and resilience | B14: 0.09 | C14: =AVERAGE('Questionnaire & Scores'!E53:E57) -> 3 | D14: =B14*100*C14/4 -> 6.75 | E14: 0.06 | F14: =AVERAGE('Questionnaire & Scores'!G53:G57) -> 3.2 | G14: =E14*100*F14/4 -> 4.8 | H14: 0.06 | I14: =AVERAGE('Questionnaire & Scores'!I53:I57) -> 2.4 | J14: =H14*100*I14/4 -> 3.6
A15: D10 — Personnel security and awareness | B15: 0.03 | C15: =AVERAGE('Questionnaire & Scores'!E59:E63) -> 3 | D15: =B15*100*C15/4 -> 2.25 | E15: 0.04 | F15: =AVERAGE('Questionnaire & Scores'!G59:G63) -> 3.4 | G15: =E15*100*F15/4 -> 3.4 | H15: 0.1 | I15: =AVERAGE('Questionnaire & Scores'!I59:I63) -> 3.4 | J15: =H15*100*I15/4 -> 8.5
A16: D11 — Subcontractor and fourth-party management | B16: 0.05 | C16: =AVERAGE('Questionnaire & Scores'!E65:E69) -> 0.4 | D16: =B16*100*C16/4 -> 0.5 | E16: 0.05 | F16: =AVERAGE('Questionnaire & Scores'!G65:G69) -> 3.4 | G16: =E16*100*F16/4 -> 4.25 | H16: 0.05 | I16: =AVERAGE('Questionnaire & Scores'!I65:I69) -> 1 | J16: =H16*100*I16/4 -> 1.25
A17: D12 — Financial viability and business resilience | B17: 0.04 | C17: =AVERAGE('Questionnaire & Scores'!E71:E75) -> 1.6 | D17: =B17*100*C17/4 -> 1.6 | E17: 0.04 | F17: =AVERAGE('Questionnaire & Scores'!G71:G75) -> 3.4 | G17: =E17*100*F17/4 -> 3.4 | H17: 0.03 | I17: =AVERAGE('Questionnaire & Scores'!I71:I75) -> 1.8 | J17: =H17*100*I17/4 -> 1.35
A18: D13 — Continuous monitoring and ongoing assurance | B18: 0.02 | C18: =AVERAGE('Questionnaire & Scores'!E77:E81) -> 1.4 | D18: =B18*100*C18/4 -> 0.7 | E18: 0.04 | F18: =AVERAGE('Questionnaire & Scores'!G77:G81) -> 3 | G18: =E18*100*F18/4 -> 3 | H18: 0.03 | I18: =AVERAGE('Questionnaire & Scores'!I77:I81) -> 1.2 | J18: =H18*100*I18/4 -> 0.9
A19: OVERALL SCORE (0–100) | B19: =SUM(B6:B18) -> 1 | D19: =SUM(D6:D18) -> 72.5 | E19: =SUM(E6:E18) -> 1 | G19: =SUM(G6:G18) -> 89.55 | H19: =SUM(H6:H18) -> 1 | J19: =SUM(J6:J18) -> 52.2
A21: RATING DERIVATION | B21: V-01 Northgate Analytics Ltd | E21: V-02 Verrio Cloud Services, Inc. | H21: V-03 Meridian BPO Solutions
A22: Overall score | B22: =D19 -> 72.5 | E22: =G19 -> 89.55 | H22: =J19 -> 52.2
A23: Base band | B23: =IF(D19>=85,"Low risk",IF(D19>=70,"Moderate risk",IF(D19>=50,"High risk","Critical risk"))) -> Moderate risk | E23: =IF(G19>=85,"Low risk",IF(G19>=70,"Moderate risk",IF(G19>=50,"High risk","Critical risk"))) -> Low risk | H23: =IF(J19>=85,"Low risk",IF(J19>=70,"Moderate risk",IF(J19>=50,"High risk","Critical risk"))) -> High risk
A24: Critical findings in escalation areas | B24: 3 | E24: 0 | H24: 1
A25: Escalation applied | B25: =IF(B24>0,"Yes — one band worse","No") -> Yes — one band worse | E25: =IF(E24>0,"Yes — one band worse","No") -> No | H25: =IF(H24>0,"Yes — one band worse","No") -> Yes — one band worse
A26: FINAL RISK RATING | B26: =CHOOSE(MIN(4,IF(D19>=85,1,IF(D19>=70,2,IF(D19>=50,3,4)))+IF(B24>0,1,0)),"Low risk","Moderate risk","High risk","Critical risk") -> High risk | E26: =CHOOSE(MIN(4,IF(G19>=85,1,IF(G19>=70,2,IF(G19>=50,3,4)))+IF(E24>0,1,0)),"Low risk","Moderate risk","High risk","Critical risk") -> Low risk | H26: =CHOOSE(MIN(4,IF(J19>=85,1,IF(J19>=70,2,IF(J19>=50,3,4)))+IF(H24>0,1,0)),"Low risk","Moderate risk","High risk","Critical risk") -> Critical risk
A27: Consequence under POL-09 | B27: =CHOOSE(MIN(4,IF(D19>=85,1,IF(D19>=70,2,IF(D19>=50,3,4)))+IF(B24>0,1,0)),"Approve. Standard reassessment cycle.","Approve with conditions. Remediation plan agreed.","Approve only with ERC sign-off, compensating controls and a dated remediation plan.","Do not approve, or terminate. Exit plan required.") -> Approve only with ERC sign-off, compensating controls and a dated remediation plan. | E27: =CHOOSE(MIN(4,IF(G19>=85,1,IF(G19>=70,2,IF(G19>=50,3,4)))+IF(E24>0,1,0)),"Approve. Standard reassessment cycle.","Approve with conditions. Remediation plan agreed.","Approve only with ERC sign-off, compensating controls and a dated remediation plan.","Do not approve, or terminate. Exit plan required.") -> Approve. Standard reassessment cycle. | H27: =CHOOSE(MIN(4,IF(J19>=85,1,IF(J19>=70,2,IF(J19>=50,3,4)))+IF(H24>0,1,0)),"Approve. Standard reassessment cycle.","Approve with conditions. Remediation plan agreed.","Approve only with ERC sign-off, compensating controls and a dated remediation plan.","Do not approve, or terminate. Exit plan required.") -> Do not approve, or terminate. Exit plan required.
A28: Decision | B28: Approve with conditions. Continue service. F-01 and F-02 are preconditions of continued Tier 1 status; contract amendment required by 31 December 2026. Reassess on delivery. | E28: Approve. No conditions. Return to the standard annual reassessment cycle, next due March 2027. | H28: Deviation from standard consequence, requiring ERC approval — see finding F-16. Immediate interim controls, 6-month risk acceptance, parallel exit-capability assessment, re-score 31 March 2027.
A30: The escalation rule is doing real work here. V-01 scores in the Moderate band and would read as an acceptable supplier on score alone. It is escalated to High because subcontractor disclosure is absent — a condition that no amount of strength elsewhere compensates for, since Aldridge cannot state where its Restricted data resides. V-03 scores 52, at the bottom of the High band, and escalates to Critical on two access-control findings. The model is deliberately structured so that a supplier cannot average its way past a control failure in an area where failure is decisive. Note also what the service-model weighting changed and did not change: Meridian is no longer scored heavily on secure development lifecycle, which is close to irrelevant to a contact centre, and is weighted instead on people, access and monitoring. Correcting that distortion moved its score by less than a point. The weighting was wrong in version 1.0 and fixing it did not rescue the supplier.

Sheet Findings & Remediation
A1: Findings and Required Remediation
A2: Consequence column states what happens if the action is not delivered by the deadline.
A3: Supplier | B3: Finding | C3: Domain | D3: Severity | E3: Finding detail | F3: Required action | G3: Deadline | H3: Consequence of non-delivery
A4: V-01 | B4: F-01 | C4: D11 | D4: Critical | E4: Subcontractor arrangements are neither disclosed nor mapped. The questionnaire response stated that no subcontractors are used; the assessment identified US-based model training processing and a hosting provider, both of which process or could access Aldridge data. | F4: Provide a complete subcontractor and fourth-party register naming every party, its role, its processing location and the data categories involved. Execute a contract amendment requiring prior notification of new subcontractors with a right to object. | G4: 31 December 2026 | H4: Suspension of new data sharing pending disclosure. Escalation to the ERC if not delivered.
A5: V-01 | B5: F-02 | C5: D8 | D5: Critical | E5: No contractual incident notification obligation exists. The agreement in force predates the current security schedule and contains no notification clause. Northgate's standard offer of 72 hours from confirmation falls short of the 24 hours from detection required by POL-02. | F5: Execute a contract amendment incorporating the current security schedule, including 24-hour notification from detection, cooperation with Aldridge investigations, and log provision within 5 business days. | G5: 31 December 2026 | H5: This is a precondition of continued Tier 1 status. Non-delivery triggers an exit assessment.
A6: V-01 | B6: F-03 | C6: D1 | D6: High | E6: The supplier has not been reassessed since October 2024, 23 months against an annual obligation under POL-09. Aldridge holds no current view of a supplier in the synchronous payment authorisation path. | F6: This assessment discharges the overdue reassessment. Record the next due date and configure automated escalation to the CISO at 30 days overdue. | G6: Complete | H6: n/a — closed by this assessment.
A7: V-01 | B7: F-04 | C7: D3 | D7: Medium | E7: Model training is performed on an aggregated dataset processed in a US region. This was disclosed only under direct questioning and does not appear in the contract or in any transfer assessment. | F7: Document the transfer, confirm the lawful mechanism with the Aldridge DPO, and record it in the processing register. Confirm whether the aggregated dataset is genuinely non-identifiable. | G7: 31 January 2027 | H7: Referral to the DPO for independent assessment under UK GDPR Articles 44-49.
A8: V-01 | B8: F-05 | C8: D8 | D8: Medium | E8: No forensic retainer and no contractual cooperation obligation. In an incident, Aldridge would depend on goodwill for evidence at the point where speed determines regulatory exposure. | F8: Include cooperation and evidence provision commitments in the contract amendment at F-02. Request that Northgate establish a DFIR retainer. | G8: 31 December 2026 | H8: Factored into the next reassessment score.
A9: V-01 | B9: F-06 | C9: D2 | D9: Low | E9: Access recertification is performed semi-annually against an Aldridge expectation of quarterly for suppliers holding Restricted data. | F9: Request a move to quarterly recertification for personnel with access to the Aldridge tenant. | G9: 30 June 2027 | H9: Monitored; not blocking.
A10: V-02 | B10: F-07 | C10: D7 | D10: Medium | E10: Log retention is 90 days hot and 12 months archived. Aldridge requested 12 months hot for investigation support; this is not currently offered. | F10: Agree an archive retrieval service level of no more than 48 hours as a compensating measure, recorded in the service schedule. | G10: 31 March 2027 | H10: Monitored; does not affect approval.
A11: V-02 | B11: F-08 | C11: D11 | D11: Low | E11: Sub-processor assessment records were provided for two of four named parties. | F11: Request the outstanding two assessment records at the next annual reassessment. | G11: March 2027 | H11: Monitored.
A12: V-02 | B12: F-09 | C12: D3 | D12: Low | E12: No UK processing region is available, which will constrain the UK entity's use of the service if data residency requirements tighten. | F12: Record as a strategic constraint in the supplier register. Review if UK volumes grow materially. | G12: Annual review | H12: Informational.
A13: V-03 | B13: F-10 | C13: D2 | D13: Critical | E13: No multi-factor authentication on the agent servicing portal used to access Aldridge customer data. Approximately 40 agents authenticate with a password alone. Administrator accounts for the same platform are standing and shared between two individuals. | F13: IMMEDIATE: route all agent access through the Aldridge-controlled dedicated access path, which enforces Aldridge MFA, and disable direct portal authentication. Meridian to enforce MFA natively and eliminate shared administrator accounts. | G13: Interim within 14 days; native MFA by 31 December 2026 | H13: Restricted-data escalation access is suspended until the interim control is in place.
A14: V-03 | B14: F-11 | C14: D5 | D14: Critical | E14: Home working was permitted for 12 agents during 2025 and remains technically possible. Remote sessions bypass the delivery centre physical controls entirely, which are the principal control this supplier relies upon, with no compensating technical control introduced. | F14: Contractually prohibit remote access to Aldridge work. Enforce technically by restricting the Aldridge access path to delivery centre source addresses. | G14: 31 December 2026 | H14: Included in the ERC escalation. Non-delivery triggers exit planning.
... A21: V-03 | B21: F-16 | C21: D1 | D21: High | E21: Overall score of 52 places Meridian in the High risk band before escalation. Two critical findings escalate the rating to Critical, which under POL-09 requires that the supplier not be approved or be terminated. | F21: Do not terminate immediately: Meridian handles live regulated dispute volume and abrupt exit would create customer harm and a regulatory exposure greater than the risk being avoided. Instead: (a) obtain formal ERC risk acceptance for a defined 6-month period; (b) implement the interim controls at F-10 and F-11 within 14 days; (c) commission a parallel exit-capability assessment identifying an alternative supplier or in-house route; (d) re-score at 31 March 2027 and terminate if the Critical rating persists. | G21: ERC decision by 30 September 2026 | H21: This is a deliberate deviation from the standard consequence for a Critical rating and must be recorded as such, with Board Audit Committee visibility.

Sheet Evidence Log
A1: Evidence Log
A2: What was reviewed, when, by whom — and what was requested and not provided.
A3: Supplier | B3: Evidence item | C3: Description | D3: Disposition | E3: Date | F3: Reviewer | G3: Observation
A4: V-01 | B4: ISO/IEC 27001:2022 certificate | C4: Certificate no. UK-2024-118432, scope statement | D4: Reviewed | E4: 2 Sep 2026 | F4: Chidi Eze | G4: Scope confirmed to cover the decisioning platform; valid to Mar 2028
A5: V-01 | B5: Penetration test report | C5: CREST-accredited firm, executive summary only | D5: Reviewed (redacted) | E5: 2 Sep 2026 | F5: Chidi Eze | G5: Full report withheld; two medium findings open per the summary
A6: V-01 | B6: Security policy set | C6: 9 documents, index with approval dates | D6: Reviewed | E6: 2 Sep 2026 | F6: Chidi Eze | G6: Board approval and current review dates evidenced
A7: V-01 | B7: Hosting agreement | C7: Supplier's own cloud provider terms | D7: Reviewed | E7: 3 Sep 2026 | F7: Elena Petrova | G7: Identified undisclosed processing arrangement; basis of finding F-01
A8: V-01 | B8: Master services agreement (Aldridge) | C8: Executed 2021 | D8: Reviewed | E8: 3 Sep 2026 | F8: Elena Petrova | G8: No security schedule, no notification clause; basis of finding F-02
A9: V-01 | B9: Audited accounts | C9: Requested | D9: Not provided | E9: 4 Sep 2026 | F9: Elena Petrova | G9: Declined. Basis of the D12 score
A10: V-02 | B10: SOC 2 Type II report | C10: Period to 31 Mar 2026, unqualified | D10: Reviewed | E10: 2 Sep 2026 | F10: Chidi Eze | G10: No exceptions relevant to the Aldridge service
A11: V-02 | B11: ISO/IEC 27001 certificate | C11: Certificate with scope statement | D11: Reviewed | E11: 2 Sep 2026 | F11: Chidi Eze | G11: Scope covers the document platform
A12: V-02 | B12: Sub-processor register | C12: 4 named parties with locations | D12: Reviewed | E12: 2 Sep 2026 | F12: Elena Petrova | G12: Assessment records provided for 2 of 4; basis of finding F-08
A13: V-02 | B13: Audited financial statements | C13: FY2025, provided under NDA | D13: Reviewed | E13: 3 Sep 2026 | F13: Elena Petrova | G13: Profitable; no going concern qualification
A14: V-02 | B14: Penetration test report and retest | C14: Full report provided | D14: Reviewed | E14: 3 Sep 2026 | F14: Chidi Eze | G14: All findings closed and retested
... A21: V-03 | B21: Group accounts | C21: Unaudited at entity level | D21: Reviewed | E21: 4 Sep 2026 | F21: Elena Petrova | G21: Entity not separately reported
A23: Items marked Not provided are as significant as the items reviewed. A supplier that declines to evidence a control has not demonstrated it, and the score reflects that rather than giving credit for the assertion. Three requests were refused across the assessment, all by suppliers already carrying material findings.

Sheet Portfolio Concentration
A1: Portfolio Concentration Analysis
A2: A supplier-by-supplier assessment cannot produce this view. It is where the estate-level exposure sits.
A3: Service or dependency | B3: Suppliers involved | C3: Concentration position | D3: Assessment
A4: Cloud hosting | B4: Northgate (undisclosed provider), Verrio (AWS), Meridian (platform vendor) | C4: Unknown | D4: Northgate's hosting provider is undisclosed. If it is AWS, Aldridge has a shared dependency it cannot see, on top of its own 100% AWS position (risk R-36). Cannot be assessed until F-01 is delivered.
A5: Fraud decisioning | B5: Northgate only | C5: Single supplier | D5: No assessed alternative for a synchronous critical-path service. Rules-based fallback covers availability, not capability. Exit plan required under the Tier 1 concentration appetite and does not exist.
A6: Document generation and e-signature | B6: Verrio only | C6: Single supplier | D6: Lower criticality; alternatives exist in a competitive market and switching is feasible within the contracted transition period.
A7: Customer support and disputes | B7: Meridian only, two sites | C7: Single supplier, undisclosed second site | D7: Both sites sit within the same group, so site failover does not diversify counterparty risk. The Cebu site is outside the Aldridge agreement (F-12).
A8: Fourth-party layer | B8: Unmapped across all three | C8: Unknown | D8: Aldridge cannot detect shared sub-processors across its Tier 1 estate. This is risk R-41 and it is unmeasurable until subcontractor disclosure is obtained from all Tier 1 and Tier 2 suppliers.
A10: Two of the five rows read Unknown, and that is the finding. Aldridge cannot measure its own supplier concentration because the fourth-party layer is unmapped. It is possible that all three suppliers sit on the same cloud provider as Aldridge itself, which would mean a single provider event removes the platform, the fraud decisioning, the document generation and the support function simultaneously. That scenario cannot currently be excluded. It is carried as risk R-41 and it is the strongest practical argument for obtaining subcontractor disclosure under finding F-01.

Sheet Jurisdiction
A1: Jurisdiction and Enforceability
A2: Added at v2.1. Contractual rights are worth what they can be enforced for, where the supplier actually is.
A3: ID | B3: Supplier | C3: Operating jurisdiction | D3: Local data protection / labour law | E3: Governing law and forum | F3: Practical enforceability | G3: Exposure
A4: V-01 | B4: Northgate Analytics Ltd | C4: England and Wales | D4: UK GDPR; Data Protection Act 2018 | E4: English law, English courts | F4: Enforceable. Same-jurisdiction as the Aldridge UK entity. Audit rights and injunctive relief are practically exercisable. | G4: Undisclosed US model-training processing (F-04) creates a transfer with no assessed mechanism. Enforceability of Aldridge rights against the undisclosed US processor is unknown because the processor is unknown.
A5: V-02 | B5: Verrio Cloud Services, Inc. | C5: Colorado, United States | D5: Colorado Privacy Act; sectoral federal law | E5: Colorado law, Denver courts | F5: Enforceable. Aldridge US entity can pursue remedies directly. No UK nexus, which constrains use by the UK entity. | G5: None material. No UK processing region limits future UK expansion but creates no present exposure.
A6: V-03 | B6: Meridian BPO Solutions | C6: Philippines | D6: Philippine Data Privacy Act 2012; Philippine labour law | E6: Philippine law, Manila arbitration | F6: Materially weaker. Enforcement requires arbitration in Manila. Injunctive relief to stop an ongoing exfiltration would be slow, and practical recovery against the entity is uncertain given the group structure at F-12. | G6: Philippine labour law constrains the disciplinary and monitoring measures Aldridge can require of Meridian in respect of its own staff. Contractual obligations to screen, monitor and discipline agents are only as good as what Meridian may lawfully do locally, and this was never assessed. Undisclosed Cebu site sits under a separate group entity, so the governing law clause may not reach the entity actually performing the work.
A8: Version 2.0 assessed all three suppliers as though a contractual obligation were equally enforceable against each. It is not. Meridian holds the weakest technical controls and sits in the jurisdiction where Aldridge's remedies are slowest and least certain, which compounds rather than offsets the position. Separately, contractual obligations requiring a supplier to screen, monitor or discipline its own staff are bounded by what local employment law permits, and that boundary was never assessed. An obligation the supplier cannot lawfully perform is not a control.

Sheet Sanctions Flow-down
A1: Sanctions and Financial Crime Flow-down
A2: OFAC liability is strict and does not transfer with the activity. A supplier's failure is Aldridge's exposure.
A3: ID | B3: Position in the flow | C3: Data or decision touched | D3: Current contractual position | E3: Severity | F3: Required action
A4: V-01 | B4: In the synchronous payment authorisation path | C4: Processes transaction and merchant data at the point of authorisation | D4: NO OBLIGATION. The agreement contains no requirement to screen, to escalate a possible match, or to preserve records of a rejected or blocked transaction. Northgate's fraud scoring may decline a transaction for fraud reasons that would also have constituted a sanctions concern, and Aldridge would receive no signal distinguishing the two. | E4: Critical | F4: Amend the agreement to require escalation of any indicator suggesting a sanctioned party, preservation of the underlying record, and cooperation with an Aldridge sanctions investigation. Confirm with Legal whether Northgate's decline logic could mask a screening event.
A5: V-02 | B5: Holds executed loan agreements and borrower identity data | C5: No transaction processing | D5: LIMITED EXPOSURE. Verrio does not make or influence a screening decision. Record preservation and production obligations are present in the current security schedule. | E5: Low | F5: Confirm at the next reassessment that record production timescales support an OFAC records request.
A6: V-03 | B6: Handles disputes and customer correspondence | C6: Human access to customer identity and account data on escalation | D6: NO OBLIGATION AND A TIPPING-OFF EXPOSURE. Agents can see account restrictions and blocked transactions without any instruction on what may be said to a customer. An agent explaining to a customer why a payment was blocked could constitute tipping off. | E6: High | F6: Issue binding handling instructions on blocked and restricted accounts, covering exactly what an agent may and may not say. Train and test on it. Add a contractual confidentiality obligation covering financial crime matters specifically.
A8: This analysis was absent from version 2.0 and is the more serious of the two additions. The questionnaire assessed information security thoroughly and asked nothing about sanctions, financial crime or tipping off. Aldridge places a supplier inside its payment authorisation path with no obligation to escalate a sanctions indicator, and places another supplier's agents in front of customers whose accounts are restricted with no instruction on what they may say. OFAC liability is strict and does not transfer with the activity: a screening failure occurring at a supplier is Aldridge's violation. Findings F-17 and F-18 are raised accordingly and should be read alongside risks R-31 and R-09.
